2024-04-12 23:32:19,930 - root - INFO - Бот запущен
2024-04-12 23:32:24,803 - root - INFO - Пользователь Leoprofi с ID 6332228115 попросил озвучить 'uybiuiyn'
2024-04-12 23:32:24,807 - root - INFO - Символов было потрачено на запросе 8. Всего было потрачено 1631. Осталось символов: 369
2024-04-12 23:32:25,524 - root - INFO - Запись успешно отправлена.
2024-04-12 23:36:07,466 - TeleBot - ERROR - Infinity polling exception: ('Connection aborted.', RemoteDisconnected('Remote end closed connection without response'))
2024-04-12 23:36:07,469 - TeleBot - ERROR - Exception traceback:
Traceback (most recent call last):
  File "C:\My_programms\JetBrains\PyCharm Community Edition 2023.3.2\My_programms\tg_voise\.venv\Lib\site-packages\urllib3\connectionpool.py", line 793, in urlopen
    response = self._make_request(
               ^^^^^^^^^^^^^^^^^^^
  File "C:\My_programms\JetBrains\PyCharm Community Edition 2023.3.2\My_programms\tg_voise\.venv\Lib\site-packages\urllib3\connectionpool.py", line 537, in _make_request
    response = conn.getresponse()
               ^^^^^^^^^^^^^^^^^^
  File "C:\My_programms\JetBrains\PyCharm Community Edition 2023.3.2\My_programms\tg_voise\.venv\Lib\site-packages\urllib3\connection.py", line 466, in getresponse
    httplib_response = super().getresponse()
                       ^^^^^^^^^^^^^^^^^^^^^
  File "C:\Users\Asus\AppData\Local\Programs\Python\Python312\Lib\http\client.py", line 1423, in getresponse
    response.begin()
  File "C:\Users\Asus\AppData\Local\Programs\Python\Python312\Lib\http\client.py", line 331, in begin
    version, status, reason = self._read_status()
                              ^^^^^^^^^^^^^^^^^^^
  File "C:\Users\Asus\AppData\Local\Programs\Python\Python312\Lib\http\client.py", line 300, in _read_status
    raise RemoteDisconnected("Remote end closed connection without"
http.client.RemoteDisconnected: Remote end closed connection without response

During handling of the above exception, another exception occurred:

Traceback (most recent call last):
  File "C:\My_programms\JetBrains\PyCharm Community Edition 2023.3.2\My_programms\tg_voise\.venv\Lib\site-packages\requests\adapters.py", line 486, in send
    resp = conn.urlopen(
           ^^^^^^^^^^^^^
  File "C:\My_programms\JetBrains\PyCharm Community Edition 2023.3.2\My_programms\tg_voise\.venv\Lib\site-packages\urllib3\connectionpool.py", line 847, in urlopen
    retries = retries.increment(
              ^^^^^^^^^^^^^^^^^^
  File "C:\My_programms\JetBrains\PyCharm Community Edition 2023.3.2\My_programms\tg_voise\.venv\Lib\site-packages\urllib3\util\retry.py", line 470, in increment
    raise reraise(type(error), error, _stacktrace)
          ^^^^^^^^^^^^^^^^^^^^^^^^^^^^^^^^^^^^^^^^
  File "C:\My_programms\JetBrains\PyCharm Community Edition 2023.3.2\My_programms\tg_voise\.venv\Lib\site-packages\urllib3\util\util.py", line 38, in reraise
    raise value.with_traceback(tb)
  File "C:\My_programms\JetBrains\PyCharm Community Edition 2023.3.2\My_programms\tg_voise\.venv\Lib\site-packages\urllib3\connectionpool.py", line 793, in urlopen
    response = self._make_request(
               ^^^^^^^^^^^^^^^^^^^
  File "C:\My_programms\JetBrains\PyCharm Community Edition 2023.3.2\My_programms\tg_voise\.venv\Lib\site-packages\urllib3\connectionpool.py", line 537, in _make_request
    response = conn.getresponse()
               ^^^^^^^^^^^^^^^^^^
  File "C:\My_programms\JetBrains\PyCharm Community Edition 2023.3.2\My_programms\tg_voise\.venv\Lib\site-packages\urllib3\connection.py", line 466, in getresponse
    httplib_response = super().getresponse()
                       ^^^^^^^^^^^^^^^^^^^^^
  File "C:\Users\Asus\AppData\Local\Programs\Python\Python312\Lib\http\client.py", line 1423, in getresponse
    response.begin()
  File "C:\Users\Asus\AppData\Local\Programs\Python\Python312\Lib\http\client.py", line 331, in begin
    version, status, reason = self._read_status()
                              ^^^^^^^^^^^^^^^^^^^
  File "C:\Users\Asus\AppData\Local\Programs\Python\Python312\Lib\http\client.py", line 300, in _read_status
    raise RemoteDisconnected("Remote end closed connection without"
urllib3.exceptions.ProtocolError: ('Connection aborted.', RemoteDisconnected('Remote end closed connection without response'))

During handling of the above exception, another exception occurred:

Traceback (most recent call last):
  File "C:\My_programms\JetBrains\PyCharm Community Edition 2023.3.2\My_programms\tg_voise\.venv\Lib\site-packages\telebot\__init__.py", line 1081, in infinity_polling
    self.polling(non_stop=True, timeout=timeout, long_polling_timeout=long_polling_timeout,
  File "C:\My_programms\JetBrains\PyCharm Community Edition 2023.3.2\My_programms\tg_voise\.venv\Lib\site-packages\telebot\__init__.py", line 1169, in polling
    self.__threaded_polling(non_stop=non_stop, interval=interval, timeout=timeout, long_polling_timeout=long_polling_timeout,
  File "C:\My_programms\JetBrains\PyCharm Community Edition 2023.3.2\My_programms\tg_voise\.venv\Lib\site-packages\telebot\__init__.py", line 1244, in __threaded_polling
    raise e
  File "C:\My_programms\JetBrains\PyCharm Community Edition 2023.3.2\My_programms\tg_voise\.venv\Lib\site-packages\telebot\__init__.py", line 1205, in __threaded_polling
    polling_thread.raise_exceptions()
  File "C:\My_programms\JetBrains\PyCharm Community Edition 2023.3.2\My_programms\tg_voise\.venv\Lib\site-packages\telebot\util.py", line 111, in raise_exceptions
    raise self.exception_info
  File "C:\My_programms\JetBrains\PyCharm Community Edition 2023.3.2\My_programms\tg_voise\.venv\Lib\site-packages\telebot\util.py", line 93, in run
    task(*args, **kwargs)
  File "C:\My_programms\JetBrains\PyCharm Community Edition 2023.3.2\My_programms\tg_voise\.venv\Lib\site-packages\telebot\__init__.py", line 675, in __retrieve_updates
    updates = self.get_updates(offset=(self.last_update_id + 1),
             ^^^^^^^^^^^^^^^^^^^^^^^^^^^^^^^^^^^^^^^^^^^^^^^^^^
  File "C:\My_programms\JetBrains\PyCharm Community Edition 2023.3.2\My_programms\tg_voise\.venv\Lib\site-packages\telebot\__init__.py", line 647, in get_updates
    json_updates = apihelper.get_updates(
                   ^^^^^^^^^^^^^^^^^^^^^^
  File "C:\My_programms\JetBrains\PyCharm Community Edition 2023.3.2\My_programms\tg_voise\.venv\Lib\site-packages\telebot\apihelper.py", line 327, in get_updates
    return _make_request(token, method_url, params=payload)
           ^^^^^^^^^^^^^^^^^^^^^^^^^^^^^^^^^^^^^^^^^^^^^^^^
  File "C:\My_programms\JetBrains\PyCharm Community Edition 2023.3.2\My_programms\tg_voise\.venv\Lib\site-packages\telebot\apihelper.py", line 161, in _make_request
    result = _get_req_session().request(
             ^^^^^^^^^^^^^^^^^^^^^^^^^^^
  File "C:\My_programms\JetBrains\PyCharm Community Edition 2023.3.2\My_programms\tg_voise\.venv\Lib\site-packages\requests\sessions.py", line 589, in request
    resp = self.send(prep, **send_kwargs)
           ^^^^^^^^^^^^^^^^^^^^^^^^^^^^^^
  File "C:\My_programms\JetBrains\PyCharm Community Edition 2023.3.2\My_programms\tg_voise\.venv\Lib\site-packages\requests\sessions.py", line 703, in send
    r = adapter.send(request, **kwargs)
        ^^^^^^^^^^^^^^^^^^^^^^^^^^^^^^^
  File "C:\My_programms\JetBrains\PyCharm Community Edition 2023.3.2\My_programms\tg_voise\.venv\Lib\site-packages\requests\adapters.py", line 501, in send
    raise ConnectionError(err, request=request)
requests.exceptions.ConnectionError: ('Connection aborted.', RemoteDisconnected('Remote end closed connection without response'))

2024-04-12 23:36:10,514 - TeleBot - ERROR - Infinity polling exception: HTTPSConnectionPool(host='api.telegram.org', port=443): Max retries exceeded with url: /bot6565406578:AAHJXXP9C3YuGGrZavTnkhlJTq4hQl1V3KE/getUpdates?offset=585466214&timeout=20 (Caused by NameResolutionError("<urllib3.connection.HTTPSConnection object at 0x0000018DBC43F410>: Failed to resolve 'api.telegram.org' ([Errno 11001] getaddrinfo failed)"))
2024-04-12 23:36:10,519 - TeleBot - ERROR - Exception traceback:
Traceback (most recent call last):
  File "C:\My_programms\JetBrains\PyCharm Community Edition 2023.3.2\My_programms\tg_voise\.venv\Lib\site-packages\urllib3\connection.py", line 198, in _new_conn
    sock = connection.create_connection(
           ^^^^^^^^^^^^^^^^^^^^^^^^^^^^^
  File "C:\My_programms\JetBrains\PyCharm Community Edition 2023.3.2\My_programms\tg_voise\.venv\Lib\site-packages\urllib3\util\connection.py", line 60, in create_connection
    for res in socket.getaddrinfo(host, port, family, socket.SOCK_STREAM):
               ^^^^^^^^^^^^^^^^^^^^^^^^^^^^^^^^^^^^^^^^^^^^^^^^^^^^^^^^^^
  File "C:\Users\Asus\AppData\Local\Programs\Python\Python312\Lib\socket.py", line 963, in getaddrinfo
    for res in _socket.getaddrinfo(host, port, family, type, proto, flags):
               ^^^^^^^^^^^^^^^^^^^^^^^^^^^^^^^^^^^^^^^^^^^^^^^^^^^^^^^^^^^
socket.gaierror: [Errno 11001] getaddrinfo failed

The above exception was the direct cause of the following exception:

Traceback (most recent call last):
  File "C:\My_programms\JetBrains\PyCharm Community Edition 2023.3.2\My_programms\tg_voise\.venv\Lib\site-packages\urllib3\connectionpool.py", line 793, in urlopen
    response = self._make_request(
               ^^^^^^^^^^^^^^^^^^^
  File "C:\My_programms\JetBrains\PyCharm Community Edition 2023.3.2\My_programms\tg_voise\.venv\Lib\site-packages\urllib3\connectionpool.py", line 491, in _make_request
    raise new_e
  File "C:\My_programms\JetBrains\PyCharm Community Edition 2023.3.2\My_programms\tg_voise\.venv\Lib\site-packages\urllib3\connectionpool.py", line 467, in _make_request
    self._validate_conn(conn)
  File "C:\My_programms\JetBrains\PyCharm Community Edition 2023.3.2\My_programms\tg_voise\.venv\Lib\site-packages\urllib3\connectionpool.py", line 1099, in _validate_conn
    conn.connect()
  File "C:\My_programms\JetBrains\PyCharm Community Edition 2023.3.2\My_programms\tg_voise\.venv\Lib\site-packages\urllib3\connection.py", line 616, in connect
    self.sock = sock = self._new_conn()
                       ^^^^^^^^^^^^^^^^
  File "C:\My_programms\JetBrains\PyCharm Community Edition 2023.3.2\My_programms\tg_voise\.venv\Lib\site-packages\urllib3\connection.py", line 205, in _new_conn
    raise NameResolutionError(self.host, self, e) from e
urllib3.exceptions.NameResolutionError: <urllib3.connection.HTTPSConnection object at 0x0000018DBC43F410>: Failed to resolve 'api.telegram.org' ([Errno 11001] getaddrinfo failed)

The above exception was the direct cause of the following exception:

Traceback (most recent call last):
  File "C:\My_programms\JetBrains\PyCharm Community Edition 2023.3.2\My_programms\tg_voise\.venv\Lib\site-packages\requests\adapters.py", line 486, in send
    resp = conn.urlopen(
           ^^^^^^^^^^^^^
  File "C:\My_programms\JetBrains\PyCharm Community Edition 2023.3.2\My_programms\tg_voise\.venv\Lib\site-packages\urllib3\connectionpool.py", line 847, in urlopen
    retries = retries.increment(
              ^^^^^^^^^^^^^^^^^^
  File "C:\My_programms\JetBrains\PyCharm Community Edition 2023.3.2\My_programms\tg_voise\.venv\Lib\site-packages\urllib3\util\retry.py", line 515, in increment
    raise MaxRetryError(_pool, url, reason) from reason  # type: ignore[arg-type]
    ^^^^^^^^^^^^^^^^^^^^^^^^^^^^^^^^^^^^^^^^^^^^^^^^^^^
urllib3.exceptions.MaxRetryError: HTTPSConnectionPool(host='api.telegram.org', port=443): Max retries exceeded with url: /bot6565406578:AAHJXXP9C3YuGGrZavTnkhlJTq4hQl1V3KE/getUpdates?offset=585466214&timeout=20 (Caused by NameResolutionError("<urllib3.connection.HTTPSConnection object at 0x0000018DBC43F410>: Failed to resolve 'api.telegram.org' ([Errno 11001] getaddrinfo failed)"))

During handling of the above exception, another exception occurred:

Traceback (most recent call last):
  File "C:\My_programms\JetBrains\PyCharm Community Edition 2023.3.2\My_programms\tg_voise\.venv\Lib\site-packages\telebot\__init__.py", line 1081, in infinity_polling
    self.polling(non_stop=True, timeout=timeout, long_polling_timeout=long_polling_timeout,
  File "C:\My_programms\JetBrains\PyCharm Community Edition 2023.3.2\My_programms\tg_voise\.venv\Lib\site-packages\telebot\__init__.py", line 1169, in polling
    self.__threaded_polling(non_stop=non_stop, interval=interval, timeout=timeout, long_polling_timeout=long_polling_timeout,
  File "C:\My_programms\JetBrains\PyCharm Community Edition 2023.3.2\My_programms\tg_voise\.venv\Lib\site-packages\telebot\__init__.py", line 1244, in __threaded_polling
    raise e
  File "C:\My_programms\JetBrains\PyCharm Community Edition 2023.3.2\My_programms\tg_voise\.venv\Lib\site-packages\telebot\__init__.py", line 1205, in __threaded_polling
    polling_thread.raise_exceptions()
  File "C:\My_programms\JetBrains\PyCharm Community Edition 2023.3.2\My_programms\tg_voise\.venv\Lib\site-packages\telebot\util.py", line 111, in raise_exceptions
    raise self.exception_info
  File "C:\My_programms\JetBrains\PyCharm Community Edition 2023.3.2\My_programms\tg_voise\.venv\Lib\site-packages\telebot\util.py", line 93, in run
    task(*args, **kwargs)
  File "C:\My_programms\JetBrains\PyCharm Community Edition 2023.3.2\My_programms\tg_voise\.venv\Lib\site-packages\telebot\__init__.py", line 675, in __retrieve_updates
    updates = self.get_updates(offset=(self.last_update_id + 1),
             ^^^^^^^^^^^^^^^^^^^^^^^^^^^^^^^^^^^^^^^^^^^^^^^^^^
  File "C:\My_programms\JetBrains\PyCharm Community Edition 2023.3.2\My_programms\tg_voise\.venv\Lib\site-packages\telebot\__init__.py", line 647, in get_updates
    json_updates = apihelper.get_updates(
                   ^^^^^^^^^^^^^^^^^^^^^^
  File "C:\My_programms\JetBrains\PyCharm Community Edition 2023.3.2\My_programms\tg_voise\.venv\Lib\site-packages\telebot\apihelper.py", line 327, in get_updates
    return _make_request(token, method_url, params=payload)
           ^^^^^^^^^^^^^^^^^^^^^^^^^^^^^^^^^^^^^^^^^^^^^^^^
  File "C:\My_programms\JetBrains\PyCharm Community Edition 2023.3.2\My_programms\tg_voise\.venv\Lib\site-packages\telebot\apihelper.py", line 161, in _make_request
    result = _get_req_session().request(
             ^^^^^^^^^^^^^^^^^^^^^^^^^^^
  File "C:\My_programms\JetBrains\PyCharm Community Edition 2023.3.2\My_programms\tg_voise\.venv\Lib\site-packages\requests\sessions.py", line 589, in request
    resp = self.send(prep, **send_kwargs)
           ^^^^^^^^^^^^^^^^^^^^^^^^^^^^^^
  File "C:\My_programms\JetBrains\PyCharm Community Edition 2023.3.2\My_programms\tg_voise\.venv\Lib\site-packages\requests\sessions.py", line 703, in send
    r = adapter.send(request, **kwargs)
        ^^^^^^^^^^^^^^^^^^^^^^^^^^^^^^^
  File "C:\My_programms\JetBrains\PyCharm Community Edition 2023.3.2\My_programms\tg_voise\.venv\Lib\site-packages\requests\adapters.py", line 519, in send
    raise ConnectionError(e, request=request)
requests.exceptions.ConnectionError: HTTPSConnectionPool(host='api.telegram.org', port=443): Max retries exceeded with url: /bot6565406578:AAHJXXP9C3YuGGrZavTnkhlJTq4hQl1V3KE/getUpdates?offset=585466214&timeout=20 (Caused by NameResolutionError("<urllib3.connection.HTTPSConnection object at 0x0000018DBC43F410>: Failed to resolve 'api.telegram.org' ([Errno 11001] getaddrinfo failed)"))

2024-04-12 23:36:13,538 - TeleBot - ERROR - Infinity polling exception: HTTPSConnectionPool(host='api.telegram.org', port=443): Max retries exceeded with url: /bot6565406578:AAHJXXP9C3YuGGrZavTnkhlJTq4hQl1V3KE/getUpdates?offset=585466214&timeout=20 (Caused by NameResolutionError("<urllib3.connection.HTTPSConnection object at 0x0000018DBCE3C620>: Failed to resolve 'api.telegram.org' ([Errno 11001] getaddrinfo failed)"))
2024-04-12 23:36:13,541 - TeleBot - ERROR - Exception traceback:
Traceback (most recent call last):
  File "C:\My_programms\JetBrains\PyCharm Community Edition 2023.3.2\My_programms\tg_voise\.venv\Lib\site-packages\urllib3\connection.py", line 198, in _new_conn
    sock = connection.create_connection(
           ^^^^^^^^^^^^^^^^^^^^^^^^^^^^^
  File "C:\My_programms\JetBrains\PyCharm Community Edition 2023.3.2\My_programms\tg_voise\.venv\Lib\site-packages\urllib3\util\connection.py", line 60, in create_connection
    for res in socket.getaddrinfo(host, port, family, socket.SOCK_STREAM):
               ^^^^^^^^^^^^^^^^^^^^^^^^^^^^^^^^^^^^^^^^^^^^^^^^^^^^^^^^^^
  File "C:\Users\Asus\AppData\Local\Programs\Python\Python312\Lib\socket.py", line 963, in getaddrinfo
    for res in _socket.getaddrinfo(host, port, family, type, proto, flags):
               ^^^^^^^^^^^^^^^^^^^^^^^^^^^^^^^^^^^^^^^^^^^^^^^^^^^^^^^^^^^
socket.gaierror: [Errno 11001] getaddrinfo failed

The above exception was the direct cause of the following exception:

Traceback (most recent call last):
  File "C:\My_programms\JetBrains\PyCharm Community Edition 2023.3.2\My_programms\tg_voise\.venv\Lib\site-packages\urllib3\connectionpool.py", line 793, in urlopen
    response = self._make_request(
               ^^^^^^^^^^^^^^^^^^^
  File "C:\My_programms\JetBrains\PyCharm Community Edition 2023.3.2\My_programms\tg_voise\.venv\Lib\site-packages\urllib3\connectionpool.py", line 491, in _make_request
    raise new_e
  File "C:\My_programms\JetBrains\PyCharm Community Edition 2023.3.2\My_programms\tg_voise\.venv\Lib\site-packages\urllib3\connectionpool.py", line 467, in _make_request
    self._validate_conn(conn)
  File "C:\My_programms\JetBrains\PyCharm Community Edition 2023.3.2\My_programms\tg_voise\.venv\Lib\site-packages\urllib3\connectionpool.py", line 1099, in _validate_conn
    conn.connect()
  File "C:\My_programms\JetBrains\PyCharm Community Edition 2023.3.2\My_programms\tg_voise\.venv\Lib\site-packages\urllib3\connection.py", line 616, in connect
    self.sock = sock = self._new_conn()
                       ^^^^^^^^^^^^^^^^
  File "C:\My_programms\JetBrains\PyCharm Community Edition 2023.3.2\My_programms\tg_voise\.venv\Lib\site-packages\urllib3\connection.py", line 205, in _new_conn
    raise NameResolutionError(self.host, self, e) from e
urllib3.exceptions.NameResolutionError: <urllib3.connection.HTTPSConnection object at 0x0000018DBCE3C620>: Failed to resolve 'api.telegram.org' ([Errno 11001] getaddrinfo failed)

The above exception was the direct cause of the following exception:

Traceback (most recent call last):
  File "C:\My_programms\JetBrains\PyCharm Community Edition 2023.3.2\My_programms\tg_voise\.venv\Lib\site-packages\requests\adapters.py", line 486, in send
    resp = conn.urlopen(
           ^^^^^^^^^^^^^
  File "C:\My_programms\JetBrains\PyCharm Community Edition 2023.3.2\My_programms\tg_voise\.venv\Lib\site-packages\urllib3\connectionpool.py", line 847, in urlopen
    retries = retries.increment(
              ^^^^^^^^^^^^^^^^^^
  File "C:\My_programms\JetBrains\PyCharm Community Edition 2023.3.2\My_programms\tg_voise\.venv\Lib\site-packages\urllib3\util\retry.py", line 515, in increment
    raise MaxRetryError(_pool, url, reason) from reason  # type: ignore[arg-type]
    ^^^^^^^^^^^^^^^^^^^^^^^^^^^^^^^^^^^^^^^^^^^^^^^^^^^
urllib3.exceptions.MaxRetryError: HTTPSConnectionPool(host='api.telegram.org', port=443): Max retries exceeded with url: /bot6565406578:AAHJXXP9C3YuGGrZavTnkhlJTq4hQl1V3KE/getUpdates?offset=585466214&timeout=20 (Caused by NameResolutionError("<urllib3.connection.HTTPSConnection object at 0x0000018DBCE3C620>: Failed to resolve 'api.telegram.org' ([Errno 11001] getaddrinfo failed)"))

During handling of the above exception, another exception occurred:

Traceback (most recent call last):
  File "C:\My_programms\JetBrains\PyCharm Community Edition 2023.3.2\My_programms\tg_voise\.venv\Lib\site-packages\telebot\__init__.py", line 1081, in infinity_polling
    self.polling(non_stop=True, timeout=timeout, long_polling_timeout=long_polling_timeout,
  File "C:\My_programms\JetBrains\PyCharm Community Edition 2023.3.2\My_programms\tg_voise\.venv\Lib\site-packages\telebot\__init__.py", line 1169, in polling
    self.__threaded_polling(non_stop=non_stop, interval=interval, timeout=timeout, long_polling_timeout=long_polling_timeout,
  File "C:\My_programms\JetBrains\PyCharm Community Edition 2023.3.2\My_programms\tg_voise\.venv\Lib\site-packages\telebot\__init__.py", line 1244, in __threaded_polling
    raise e
  File "C:\My_programms\JetBrains\PyCharm Community Edition 2023.3.2\My_programms\tg_voise\.venv\Lib\site-packages\telebot\__init__.py", line 1205, in __threaded_polling
    polling_thread.raise_exceptions()
  File "C:\My_programms\JetBrains\PyCharm Community Edition 2023.3.2\My_programms\tg_voise\.venv\Lib\site-packages\telebot\util.py", line 111, in raise_exceptions
    raise self.exception_info
  File "C:\My_programms\JetBrains\PyCharm Community Edition 2023.3.2\My_programms\tg_voise\.venv\Lib\site-packages\telebot\util.py", line 93, in run
    task(*args, **kwargs)
  File "C:\My_programms\JetBrains\PyCharm Community Edition 2023.3.2\My_programms\tg_voise\.venv\Lib\site-packages\telebot\__init__.py", line 675, in __retrieve_updates
    updates = self.get_updates(offset=(self.last_update_id + 1),
             ^^^^^^^^^^^^^^^^^^^^^^^^^^^^^^^^^^^^^^^^^^^^^^^^^^
  File "C:\My_programms\JetBrains\PyCharm Community Edition 2023.3.2\My_programms\tg_voise\.venv\Lib\site-packages\telebot\__init__.py", line 647, in get_updates
    json_updates = apihelper.get_updates(
                   ^^^^^^^^^^^^^^^^^^^^^^
  File "C:\My_programms\JetBrains\PyCharm Community Edition 2023.3.2\My_programms\tg_voise\.venv\Lib\site-packages\telebot\apihelper.py", line 327, in get_updates
    return _make_request(token, method_url, params=payload)
           ^^^^^^^^^^^^^^^^^^^^^^^^^^^^^^^^^^^^^^^^^^^^^^^^
  File "C:\My_programms\JetBrains\PyCharm Community Edition 2023.3.2\My_programms\tg_voise\.venv\Lib\site-packages\telebot\apihelper.py", line 161, in _make_request
    result = _get_req_session().request(
             ^^^^^^^^^^^^^^^^^^^^^^^^^^^
  File "C:\My_programms\JetBrains\PyCharm Community Edition 2023.3.2\My_programms\tg_voise\.venv\Lib\site-packages\requests\sessions.py", line 589, in request
    resp = self.send(prep, **send_kwargs)
           ^^^^^^^^^^^^^^^^^^^^^^^^^^^^^^
  File "C:\My_programms\JetBrains\PyCharm Community Edition 2023.3.2\My_programms\tg_voise\.venv\Lib\site-packages\requests\sessions.py", line 703, in send
    r = adapter.send(request, **kwargs)
        ^^^^^^^^^^^^^^^^^^^^^^^^^^^^^^^
  File "C:\My_programms\JetBrains\PyCharm Community Edition 2023.3.2\My_programms\tg_voise\.venv\Lib\site-packages\requests\adapters.py", line 519, in send
    raise ConnectionError(e, request=request)
requests.exceptions.ConnectionError: HTTPSConnectionPool(host='api.telegram.org', port=443): Max retries exceeded with url: /bot6565406578:AAHJXXP9C3YuGGrZavTnkhlJTq4hQl1V3KE/getUpdates?offset=585466214&timeout=20 (Caused by NameResolutionError("<urllib3.connection.HTTPSConnection object at 0x0000018DBCE3C620>: Failed to resolve 'api.telegram.org' ([Errno 11001] getaddrinfo failed)"))

2024-04-12 23:36:28,612 - TeleBot - ERROR - Infinity polling exception: HTTPSConnectionPool(host='api.telegram.org', port=443): Max retries exceeded with url: /bot6565406578:AAHJXXP9C3YuGGrZavTnkhlJTq4hQl1V3KE/getUpdates?offset=585466214&timeout=20 (Caused by NameResolutionError("<urllib3.connection.HTTPSConnection object at 0x0000018DBC43D340>: Failed to resolve 'api.telegram.org' ([Errno 11001] getaddrinfo failed)"))
2024-04-12 23:36:28,616 - TeleBot - ERROR - Exception traceback:
Traceback (most recent call last):
  File "C:\My_programms\JetBrains\PyCharm Community Edition 2023.3.2\My_programms\tg_voise\.venv\Lib\site-packages\urllib3\connection.py", line 198, in _new_conn
    sock = connection.create_connection(
           ^^^^^^^^^^^^^^^^^^^^^^^^^^^^^
  File "C:\My_programms\JetBrains\PyCharm Community Edition 2023.3.2\My_programms\tg_voise\.venv\Lib\site-packages\urllib3\util\connection.py", line 60, in create_connection
    for res in socket.getaddrinfo(host, port, family, socket.SOCK_STREAM):
               ^^^^^^^^^^^^^^^^^^^^^^^^^^^^^^^^^^^^^^^^^^^^^^^^^^^^^^^^^^
  File "C:\Users\Asus\AppData\Local\Programs\Python\Python312\Lib\socket.py", line 963, in getaddrinfo
    for res in _socket.getaddrinfo(host, port, family, type, proto, flags):
               ^^^^^^^^^^^^^^^^^^^^^^^^^^^^^^^^^^^^^^^^^^^^^^^^^^^^^^^^^^^
socket.gaierror: [Errno 11001] getaddrinfo failed

The above exception was the direct cause of the following exception:

Traceback (most recent call last):
  File "C:\My_programms\JetBrains\PyCharm Community Edition 2023.3.2\My_programms\tg_voise\.venv\Lib\site-packages\urllib3\connectionpool.py", line 793, in urlopen
    response = self._make_request(
               ^^^^^^^^^^^^^^^^^^^
  File "C:\My_programms\JetBrains\PyCharm Community Edition 2023.3.2\My_programms\tg_voise\.venv\Lib\site-packages\urllib3\connectionpool.py", line 491, in _make_request
    raise new_e
  File "C:\My_programms\JetBrains\PyCharm Community Edition 2023.3.2\My_programms\tg_voise\.venv\Lib\site-packages\urllib3\connectionpool.py", line 467, in _make_request
    self._validate_conn(conn)
  File "C:\My_programms\JetBrains\PyCharm Community Edition 2023.3.2\My_programms\tg_voise\.venv\Lib\site-packages\urllib3\connectionpool.py", line 1099, in _validate_conn
    conn.connect()
  File "C:\My_programms\JetBrains\PyCharm Community Edition 2023.3.2\My_programms\tg_voise\.venv\Lib\site-packages\urllib3\connection.py", line 616, in connect
    self.sock = sock = self._new_conn()
                       ^^^^^^^^^^^^^^^^
  File "C:\My_programms\JetBrains\PyCharm Community Edition 2023.3.2\My_programms\tg_voise\.venv\Lib\site-packages\urllib3\connection.py", line 205, in _new_conn
    raise NameResolutionError(self.host, self, e) from e
urllib3.exceptions.NameResolutionError: <urllib3.connection.HTTPSConnection object at 0x0000018DBC43D340>: Failed to resolve 'api.telegram.org' ([Errno 11001] getaddrinfo failed)

The above exception was the direct cause of the following exception:

Traceback (most recent call last):
  File "C:\My_programms\JetBrains\PyCharm Community Edition 2023.3.2\My_programms\tg_voise\.venv\Lib\site-packages\requests\adapters.py", line 486, in send
    resp = conn.urlopen(
           ^^^^^^^^^^^^^
  File "C:\My_programms\JetBrains\PyCharm Community Edition 2023.3.2\My_programms\tg_voise\.venv\Lib\site-packages\urllib3\connectionpool.py", line 847, in urlopen
    retries = retries.increment(
              ^^^^^^^^^^^^^^^^^^
  File "C:\My_programms\JetBrains\PyCharm Community Edition 2023.3.2\My_programms\tg_voise\.venv\Lib\site-packages\urllib3\util\retry.py", line 515, in increment
    raise MaxRetryError(_pool, url, reason) from reason  # type: ignore[arg-type]
    ^^^^^^^^^^^^^^^^^^^^^^^^^^^^^^^^^^^^^^^^^^^^^^^^^^^
urllib3.exceptions.MaxRetryError: HTTPSConnectionPool(host='api.telegram.org', port=443): Max retries exceeded with url: /bot6565406578:AAHJXXP9C3YuGGrZavTnkhlJTq4hQl1V3KE/getUpdates?offset=585466214&timeout=20 (Caused by NameResolutionError("<urllib3.connection.HTTPSConnection object at 0x0000018DBC43D340>: Failed to resolve 'api.telegram.org' ([Errno 11001] getaddrinfo failed)"))

During handling of the above exception, another exception occurred:

Traceback (most recent call last):
  File "C:\My_programms\JetBrains\PyCharm Community Edition 2023.3.2\My_programms\tg_voise\.venv\Lib\site-packages\telebot\__init__.py", line 1081, in infinity_polling
    self.polling(non_stop=True, timeout=timeout, long_polling_timeout=long_polling_timeout,
  File "C:\My_programms\JetBrains\PyCharm Community Edition 2023.3.2\My_programms\tg_voise\.venv\Lib\site-packages\telebot\__init__.py", line 1169, in polling
    self.__threaded_polling(non_stop=non_stop, interval=interval, timeout=timeout, long_polling_timeout=long_polling_timeout,
  File "C:\My_programms\JetBrains\PyCharm Community Edition 2023.3.2\My_programms\tg_voise\.venv\Lib\site-packages\telebot\__init__.py", line 1244, in __threaded_polling
    raise e
  File "C:\My_programms\JetBrains\PyCharm Community Edition 2023.3.2\My_programms\tg_voise\.venv\Lib\site-packages\telebot\__init__.py", line 1205, in __threaded_polling
    polling_thread.raise_exceptions()
  File "C:\My_programms\JetBrains\PyCharm Community Edition 2023.3.2\My_programms\tg_voise\.venv\Lib\site-packages\telebot\util.py", line 111, in raise_exceptions
    raise self.exception_info
  File "C:\My_programms\JetBrains\PyCharm Community Edition 2023.3.2\My_programms\tg_voise\.venv\Lib\site-packages\telebot\util.py", line 93, in run
    task(*args, **kwargs)
  File "C:\My_programms\JetBrains\PyCharm Community Edition 2023.3.2\My_programms\tg_voise\.venv\Lib\site-packages\telebot\__init__.py", line 675, in __retrieve_updates
    updates = self.get_updates(offset=(self.last_update_id + 1),
             ^^^^^^^^^^^^^^^^^^^^^^^^^^^^^^^^^^^^^^^^^^^^^^^^^^
  File "C:\My_programms\JetBrains\PyCharm Community Edition 2023.3.2\My_programms\tg_voise\.venv\Lib\site-packages\telebot\__init__.py", line 647, in get_updates
    json_updates = apihelper.get_updates(
                   ^^^^^^^^^^^^^^^^^^^^^^
  File "C:\My_programms\JetBrains\PyCharm Community Edition 2023.3.2\My_programms\tg_voise\.venv\Lib\site-packages\telebot\apihelper.py", line 327, in get_updates
    return _make_request(token, method_url, params=payload)
           ^^^^^^^^^^^^^^^^^^^^^^^^^^^^^^^^^^^^^^^^^^^^^^^^
  File "C:\My_programms\JetBrains\PyCharm Community Edition 2023.3.2\My_programms\tg_voise\.venv\Lib\site-packages\telebot\apihelper.py", line 161, in _make_request
    result = _get_req_session().request(
             ^^^^^^^^^^^^^^^^^^^^^^^^^^^
  File "C:\My_programms\JetBrains\PyCharm Community Edition 2023.3.2\My_programms\tg_voise\.venv\Lib\site-packages\requests\sessions.py", line 589, in request
    resp = self.send(prep, **send_kwargs)
           ^^^^^^^^^^^^^^^^^^^^^^^^^^^^^^
  File "C:\My_programms\JetBrains\PyCharm Community Edition 2023.3.2\My_programms\tg_voise\.venv\Lib\site-packages\requests\sessions.py", line 703, in send
    r = adapter.send(request, **kwargs)
        ^^^^^^^^^^^^^^^^^^^^^^^^^^^^^^^
  File "C:\My_programms\JetBrains\PyCharm Community Edition 2023.3.2\My_programms\tg_voise\.venv\Lib\site-packages\requests\adapters.py", line 519, in send
    raise ConnectionError(e, request=request)
requests.exceptions.ConnectionError: HTTPSConnectionPool(host='api.telegram.org', port=443): Max retries exceeded with url: /bot6565406578:AAHJXXP9C3YuGGrZavTnkhlJTq4hQl1V3KE/getUpdates?offset=585466214&timeout=20 (Caused by NameResolutionError("<urllib3.connection.HTTPSConnection object at 0x0000018DBC43D340>: Failed to resolve 'api.telegram.org' ([Errno 11001] getaddrinfo failed)"))

2024-04-12 23:36:43,664 - TeleBot - ERROR - Infinity polling exception: HTTPSConnectionPool(host='api.telegram.org', port=443): Max retries exceeded with url: /bot6565406578:AAHJXXP9C3YuGGrZavTnkhlJTq4hQl1V3KE/getUpdates?offset=585466214&timeout=20 (Caused by NameResolutionError("<urllib3.connection.HTTPSConnection object at 0x0000018DBCE3D5E0>: Failed to resolve 'api.telegram.org' ([Errno 11001] getaddrinfo failed)"))
2024-04-12 23:36:43,668 - TeleBot - ERROR - Exception traceback:
Traceback (most recent call last):
  File "C:\My_programms\JetBrains\PyCharm Community Edition 2023.3.2\My_programms\tg_voise\.venv\Lib\site-packages\urllib3\connection.py", line 198, in _new_conn
    sock = connection.create_connection(
           ^^^^^^^^^^^^^^^^^^^^^^^^^^^^^
  File "C:\My_programms\JetBrains\PyCharm Community Edition 2023.3.2\My_programms\tg_voise\.venv\Lib\site-packages\urllib3\util\connection.py", line 60, in create_connection
    for res in socket.getaddrinfo(host, port, family, socket.SOCK_STREAM):
               ^^^^^^^^^^^^^^^^^^^^^^^^^^^^^^^^^^^^^^^^^^^^^^^^^^^^^^^^^^
  File "C:\Users\Asus\AppData\Local\Programs\Python\Python312\Lib\socket.py", line 963, in getaddrinfo
    for res in _socket.getaddrinfo(host, port, family, type, proto, flags):
               ^^^^^^^^^^^^^^^^^^^^^^^^^^^^^^^^^^^^^^^^^^^^^^^^^^^^^^^^^^^
socket.gaierror: [Errno 11001] getaddrinfo failed

The above exception was the direct cause of the following exception:

Traceback (most recent call last):
  File "C:\My_programms\JetBrains\PyCharm Community Edition 2023.3.2\My_programms\tg_voise\.venv\Lib\site-packages\urllib3\connectionpool.py", line 793, in urlopen
    response = self._make_request(
               ^^^^^^^^^^^^^^^^^^^
  File "C:\My_programms\JetBrains\PyCharm Community Edition 2023.3.2\My_programms\tg_voise\.venv\Lib\site-packages\urllib3\connectionpool.py", line 491, in _make_request
    raise new_e
  File "C:\My_programms\JetBrains\PyCharm Community Edition 2023.3.2\My_programms\tg_voise\.venv\Lib\site-packages\urllib3\connectionpool.py", line 467, in _make_request
    self._validate_conn(conn)
  File "C:\My_programms\JetBrains\PyCharm Community Edition 2023.3.2\My_programms\tg_voise\.venv\Lib\site-packages\urllib3\connectionpool.py", line 1099, in _validate_conn
    conn.connect()
  File "C:\My_programms\JetBrains\PyCharm Community Edition 2023.3.2\My_programms\tg_voise\.venv\Lib\site-packages\urllib3\connection.py", line 616, in connect
    self.sock = sock = self._new_conn()
                       ^^^^^^^^^^^^^^^^
  File "C:\My_programms\JetBrains\PyCharm Community Edition 2023.3.2\My_programms\tg_voise\.venv\Lib\site-packages\urllib3\connection.py", line 205, in _new_conn
    raise NameResolutionError(self.host, self, e) from e
urllib3.exceptions.NameResolutionError: <urllib3.connection.HTTPSConnection object at 0x0000018DBCE3D5E0>: Failed to resolve 'api.telegram.org' ([Errno 11001] getaddrinfo failed)

The above exception was the direct cause of the following exception:

Traceback (most recent call last):
  File "C:\My_programms\JetBrains\PyCharm Community Edition 2023.3.2\My_programms\tg_voise\.venv\Lib\site-packages\requests\adapters.py", line 486, in send
    resp = conn.urlopen(
           ^^^^^^^^^^^^^
  File "C:\My_programms\JetBrains\PyCharm Community Edition 2023.3.2\My_programms\tg_voise\.venv\Lib\site-packages\urllib3\connectionpool.py", line 847, in urlopen
    retries = retries.increment(
              ^^^^^^^^^^^^^^^^^^
  File "C:\My_programms\JetBrains\PyCharm Community Edition 2023.3.2\My_programms\tg_voise\.venv\Lib\site-packages\urllib3\util\retry.py", line 515, in increment
    raise MaxRetryError(_pool, url, reason) from reason  # type: ignore[arg-type]
    ^^^^^^^^^^^^^^^^^^^^^^^^^^^^^^^^^^^^^^^^^^^^^^^^^^^
urllib3.exceptions.MaxRetryError: HTTPSConnectionPool(host='api.telegram.org', port=443): Max retries exceeded with url: /bot6565406578:AAHJXXP9C3YuGGrZavTnkhlJTq4hQl1V3KE/getUpdates?offset=585466214&timeout=20 (Caused by NameResolutionError("<urllib3.connection.HTTPSConnection object at 0x0000018DBCE3D5E0>: Failed to resolve 'api.telegram.org' ([Errno 11001] getaddrinfo failed)"))

During handling of the above exception, another exception occurred:

Traceback (most recent call last):
  File "C:\My_programms\JetBrains\PyCharm Community Edition 2023.3.2\My_programms\tg_voise\.venv\Lib\site-packages\telebot\__init__.py", line 1081, in infinity_polling
    self.polling(non_stop=True, timeout=timeout, long_polling_timeout=long_polling_timeout,
  File "C:\My_programms\JetBrains\PyCharm Community Edition 2023.3.2\My_programms\tg_voise\.venv\Lib\site-packages\telebot\__init__.py", line 1169, in polling
    self.__threaded_polling(non_stop=non_stop, interval=interval, timeout=timeout, long_polling_timeout=long_polling_timeout,
  File "C:\My_programms\JetBrains\PyCharm Community Edition 2023.3.2\My_programms\tg_voise\.venv\Lib\site-packages\telebot\__init__.py", line 1244, in __threaded_polling
    raise e
  File "C:\My_programms\JetBrains\PyCharm Community Edition 2023.3.2\My_programms\tg_voise\.venv\Lib\site-packages\telebot\__init__.py", line 1205, in __threaded_polling
    polling_thread.raise_exceptions()
  File "C:\My_programms\JetBrains\PyCharm Community Edition 2023.3.2\My_programms\tg_voise\.venv\Lib\site-packages\telebot\util.py", line 111, in raise_exceptions
    raise self.exception_info
  File "C:\My_programms\JetBrains\PyCharm Community Edition 2023.3.2\My_programms\tg_voise\.venv\Lib\site-packages\telebot\util.py", line 93, in run
    task(*args, **kwargs)
  File "C:\My_programms\JetBrains\PyCharm Community Edition 2023.3.2\My_programms\tg_voise\.venv\Lib\site-packages\telebot\__init__.py", line 675, in __retrieve_updates
    updates = self.get_updates(offset=(self.last_update_id + 1),
             ^^^^^^^^^^^^^^^^^^^^^^^^^^^^^^^^^^^^^^^^^^^^^^^^^^
  File "C:\My_programms\JetBrains\PyCharm Community Edition 2023.3.2\My_programms\tg_voise\.venv\Lib\site-packages\telebot\__init__.py", line 647, in get_updates
    json_updates = apihelper.get_updates(
                   ^^^^^^^^^^^^^^^^^^^^^^
  File "C:\My_programms\JetBrains\PyCharm Community Edition 2023.3.2\My_programms\tg_voise\.venv\Lib\site-packages\telebot\apihelper.py", line 327, in get_updates
    return _make_request(token, method_url, params=payload)
           ^^^^^^^^^^^^^^^^^^^^^^^^^^^^^^^^^^^^^^^^^^^^^^^^
  File "C:\My_programms\JetBrains\PyCharm Community Edition 2023.3.2\My_programms\tg_voise\.venv\Lib\site-packages\telebot\apihelper.py", line 161, in _make_request
    result = _get_req_session().request(
             ^^^^^^^^^^^^^^^^^^^^^^^^^^^
  File "C:\My_programms\JetBrains\PyCharm Community Edition 2023.3.2\My_programms\tg_voise\.venv\Lib\site-packages\requests\sessions.py", line 589, in request
    resp = self.send(prep, **send_kwargs)
           ^^^^^^^^^^^^^^^^^^^^^^^^^^^^^^
  File "C:\My_programms\JetBrains\PyCharm Community Edition 2023.3.2\My_programms\tg_voise\.venv\Lib\site-packages\requests\sessions.py", line 703, in send
    r = adapter.send(request, **kwargs)
        ^^^^^^^^^^^^^^^^^^^^^^^^^^^^^^^
  File "C:\My_programms\JetBrains\PyCharm Community Edition 2023.3.2\My_programms\tg_voise\.venv\Lib\site-packages\requests\adapters.py", line 519, in send
    raise ConnectionError(e, request=request)
requests.exceptions.ConnectionError: HTTPSConnectionPool(host='api.telegram.org', port=443): Max retries exceeded with url: /bot6565406578:AAHJXXP9C3YuGGrZavTnkhlJTq4hQl1V3KE/getUpdates?offset=585466214&timeout=20 (Caused by NameResolutionError("<urllib3.connection.HTTPSConnection object at 0x0000018DBCE3D5E0>: Failed to resolve 'api.telegram.org' ([Errno 11001] getaddrinfo failed)"))

2024-04-12 23:36:58,737 - TeleBot - ERROR - Infinity polling exception: HTTPSConnectionPool(host='api.telegram.org', port=443): Max retries exceeded with url: /bot6565406578:AAHJXXP9C3YuGGrZavTnkhlJTq4hQl1V3KE/getUpdates?offset=585466214&timeout=20 (Caused by NameResolutionError("<urllib3.connection.HTTPSConnection object at 0x0000018DBCE3E6C0>: Failed to resolve 'api.telegram.org' ([Errno 11001] getaddrinfo failed)"))
2024-04-12 23:36:58,740 - TeleBot - ERROR - Exception traceback:
Traceback (most recent call last):
  File "C:\My_programms\JetBrains\PyCharm Community Edition 2023.3.2\My_programms\tg_voise\.venv\Lib\site-packages\urllib3\connection.py", line 198, in _new_conn
    sock = connection.create_connection(
           ^^^^^^^^^^^^^^^^^^^^^^^^^^^^^
  File "C:\My_programms\JetBrains\PyCharm Community Edition 2023.3.2\My_programms\tg_voise\.venv\Lib\site-packages\urllib3\util\connection.py", line 60, in create_connection
    for res in socket.getaddrinfo(host, port, family, socket.SOCK_STREAM):
               ^^^^^^^^^^^^^^^^^^^^^^^^^^^^^^^^^^^^^^^^^^^^^^^^^^^^^^^^^^
  File "C:\Users\Asus\AppData\Local\Programs\Python\Python312\Lib\socket.py", line 963, in getaddrinfo
    for res in _socket.getaddrinfo(host, port, family, type, proto, flags):
               ^^^^^^^^^^^^^^^^^^^^^^^^^^^^^^^^^^^^^^^^^^^^^^^^^^^^^^^^^^^
socket.gaierror: [Errno 11001] getaddrinfo failed

The above exception was the direct cause of the following exception:

Traceback (most recent call last):
  File "C:\My_programms\JetBrains\PyCharm Community Edition 2023.3.2\My_programms\tg_voise\.venv\Lib\site-packages\urllib3\connectionpool.py", line 793, in urlopen
    response = self._make_request(
               ^^^^^^^^^^^^^^^^^^^
  File "C:\My_programms\JetBrains\PyCharm Community Edition 2023.3.2\My_programms\tg_voise\.venv\Lib\site-packages\urllib3\connectionpool.py", line 491, in _make_request
    raise new_e
  File "C:\My_programms\JetBrains\PyCharm Community Edition 2023.3.2\My_programms\tg_voise\.venv\Lib\site-packages\urllib3\connectionpool.py", line 467, in _make_request
    self._validate_conn(conn)
  File "C:\My_programms\JetBrains\PyCharm Community Edition 2023.3.2\My_programms\tg_voise\.venv\Lib\site-packages\urllib3\connectionpool.py", line 1099, in _validate_conn
    conn.connect()
  File "C:\My_programms\JetBrains\PyCharm Community Edition 2023.3.2\My_programms\tg_voise\.venv\Lib\site-packages\urllib3\connection.py", line 616, in connect
    self.sock = sock = self._new_conn()
                       ^^^^^^^^^^^^^^^^
  File "C:\My_programms\JetBrains\PyCharm Community Edition 2023.3.2\My_programms\tg_voise\.venv\Lib\site-packages\urllib3\connection.py", line 205, in _new_conn
    raise NameResolutionError(self.host, self, e) from e
urllib3.exceptions.NameResolutionError: <urllib3.connection.HTTPSConnection object at 0x0000018DBCE3E6C0>: Failed to resolve 'api.telegram.org' ([Errno 11001] getaddrinfo failed)

The above exception was the direct cause of the following exception:

Traceback (most recent call last):
  File "C:\My_programms\JetBrains\PyCharm Community Edition 2023.3.2\My_programms\tg_voise\.venv\Lib\site-packages\requests\adapters.py", line 486, in send
    resp = conn.urlopen(
           ^^^^^^^^^^^^^
  File "C:\My_programms\JetBrains\PyCharm Community Edition 2023.3.2\My_programms\tg_voise\.venv\Lib\site-packages\urllib3\connectionpool.py", line 847, in urlopen
    retries = retries.increment(
              ^^^^^^^^^^^^^^^^^^
  File "C:\My_programms\JetBrains\PyCharm Community Edition 2023.3.2\My_programms\tg_voise\.venv\Lib\site-packages\urllib3\util\retry.py", line 515, in increment
    raise MaxRetryError(_pool, url, reason) from reason  # type: ignore[arg-type]
    ^^^^^^^^^^^^^^^^^^^^^^^^^^^^^^^^^^^^^^^^^^^^^^^^^^^
urllib3.exceptions.MaxRetryError: HTTPSConnectionPool(host='api.telegram.org', port=443): Max retries exceeded with url: /bot6565406578:AAHJXXP9C3YuGGrZavTnkhlJTq4hQl1V3KE/getUpdates?offset=585466214&timeout=20 (Caused by NameResolutionError("<urllib3.connection.HTTPSConnection object at 0x0000018DBCE3E6C0>: Failed to resolve 'api.telegram.org' ([Errno 11001] getaddrinfo failed)"))

During handling of the above exception, another exception occurred:

Traceback (most recent call last):
  File "C:\My_programms\JetBrains\PyCharm Community Edition 2023.3.2\My_programms\tg_voise\.venv\Lib\site-packages\telebot\__init__.py", line 1081, in infinity_polling
    self.polling(non_stop=True, timeout=timeout, long_polling_timeout=long_polling_timeout,
  File "C:\My_programms\JetBrains\PyCharm Community Edition 2023.3.2\My_programms\tg_voise\.venv\Lib\site-packages\telebot\__init__.py", line 1169, in polling
    self.__threaded_polling(non_stop=non_stop, interval=interval, timeout=timeout, long_polling_timeout=long_polling_timeout,
  File "C:\My_programms\JetBrains\PyCharm Community Edition 2023.3.2\My_programms\tg_voise\.venv\Lib\site-packages\telebot\__init__.py", line 1244, in __threaded_polling
    raise e
  File "C:\My_programms\JetBrains\PyCharm Community Edition 2023.3.2\My_programms\tg_voise\.venv\Lib\site-packages\telebot\__init__.py", line 1205, in __threaded_polling
    polling_thread.raise_exceptions()
  File "C:\My_programms\JetBrains\PyCharm Community Edition 2023.3.2\My_programms\tg_voise\.venv\Lib\site-packages\telebot\util.py", line 111, in raise_exceptions
    raise self.exception_info
  File "C:\My_programms\JetBrains\PyCharm Community Edition 2023.3.2\My_programms\tg_voise\.venv\Lib\site-packages\telebot\util.py", line 93, in run
    task(*args, **kwargs)
  File "C:\My_programms\JetBrains\PyCharm Community Edition 2023.3.2\My_programms\tg_voise\.venv\Lib\site-packages\telebot\__init__.py", line 675, in __retrieve_updates
    updates = self.get_updates(offset=(self.last_update_id + 1),
             ^^^^^^^^^^^^^^^^^^^^^^^^^^^^^^^^^^^^^^^^^^^^^^^^^^
  File "C:\My_programms\JetBrains\PyCharm Community Edition 2023.3.2\My_programms\tg_voise\.venv\Lib\site-packages\telebot\__init__.py", line 647, in get_updates
    json_updates = apihelper.get_updates(
                   ^^^^^^^^^^^^^^^^^^^^^^
  File "C:\My_programms\JetBrains\PyCharm Community Edition 2023.3.2\My_programms\tg_voise\.venv\Lib\site-packages\telebot\apihelper.py", line 327, in get_updates
    return _make_request(token, method_url, params=payload)
           ^^^^^^^^^^^^^^^^^^^^^^^^^^^^^^^^^^^^^^^^^^^^^^^^
  File "C:\My_programms\JetBrains\PyCharm Community Edition 2023.3.2\My_programms\tg_voise\.venv\Lib\site-packages\telebot\apihelper.py", line 161, in _make_request
    result = _get_req_session().request(
             ^^^^^^^^^^^^^^^^^^^^^^^^^^^
  File "C:\My_programms\JetBrains\PyCharm Community Edition 2023.3.2\My_programms\tg_voise\.venv\Lib\site-packages\requests\sessions.py", line 589, in request
    resp = self.send(prep, **send_kwargs)
           ^^^^^^^^^^^^^^^^^^^^^^^^^^^^^^
  File "C:\My_programms\JetBrains\PyCharm Community Edition 2023.3.2\My_programms\tg_voise\.venv\Lib\site-packages\requests\sessions.py", line 703, in send
    r = adapter.send(request, **kwargs)
        ^^^^^^^^^^^^^^^^^^^^^^^^^^^^^^^
  File "C:\My_programms\JetBrains\PyCharm Community Edition 2023.3.2\My_programms\tg_voise\.venv\Lib\site-packages\requests\adapters.py", line 519, in send
    raise ConnectionError(e, request=request)
requests.exceptions.ConnectionError: HTTPSConnectionPool(host='api.telegram.org', port=443): Max retries exceeded with url: /bot6565406578:AAHJXXP9C3YuGGrZavTnkhlJTq4hQl1V3KE/getUpdates?offset=585466214&timeout=20 (Caused by NameResolutionError("<urllib3.connection.HTTPSConnection object at 0x0000018DBCE3E6C0>: Failed to resolve 'api.telegram.org' ([Errno 11001] getaddrinfo failed)"))

2024-04-12 23:37:13,813 - TeleBot - ERROR - Infinity polling exception: HTTPSConnectionPool(host='api.telegram.org', port=443): Max retries exceeded with url: /bot6565406578:AAHJXXP9C3YuGGrZavTnkhlJTq4hQl1V3KE/getUpdates?offset=585466214&timeout=20 (Caused by NameResolutionError("<urllib3.connection.HTTPSConnection object at 0x0000018DBC43ED80>: Failed to resolve 'api.telegram.org' ([Errno 11001] getaddrinfo failed)"))
2024-04-12 23:37:13,817 - TeleBot - ERROR - Exception traceback:
Traceback (most recent call last):
  File "C:\My_programms\JetBrains\PyCharm Community Edition 2023.3.2\My_programms\tg_voise\.venv\Lib\site-packages\urllib3\connection.py", line 198, in _new_conn
    sock = connection.create_connection(
           ^^^^^^^^^^^^^^^^^^^^^^^^^^^^^
  File "C:\My_programms\JetBrains\PyCharm Community Edition 2023.3.2\My_programms\tg_voise\.venv\Lib\site-packages\urllib3\util\connection.py", line 60, in create_connection
    for res in socket.getaddrinfo(host, port, family, socket.SOCK_STREAM):
               ^^^^^^^^^^^^^^^^^^^^^^^^^^^^^^^^^^^^^^^^^^^^^^^^^^^^^^^^^^
  File "C:\Users\Asus\AppData\Local\Programs\Python\Python312\Lib\socket.py", line 963, in getaddrinfo
    for res in _socket.getaddrinfo(host, port, family, type, proto, flags):
               ^^^^^^^^^^^^^^^^^^^^^^^^^^^^^^^^^^^^^^^^^^^^^^^^^^^^^^^^^^^
socket.gaierror: [Errno 11001] getaddrinfo failed

The above exception was the direct cause of the following exception:

Traceback (most recent call last):
  File "C:\My_programms\JetBrains\PyCharm Community Edition 2023.3.2\My_programms\tg_voise\.venv\Lib\site-packages\urllib3\connectionpool.py", line 793, in urlopen
    response = self._make_request(
               ^^^^^^^^^^^^^^^^^^^
  File "C:\My_programms\JetBrains\PyCharm Community Edition 2023.3.2\My_programms\tg_voise\.venv\Lib\site-packages\urllib3\connectionpool.py", line 491, in _make_request
    raise new_e
  File "C:\My_programms\JetBrains\PyCharm Community Edition 2023.3.2\My_programms\tg_voise\.venv\Lib\site-packages\urllib3\connectionpool.py", line 467, in _make_request
    self._validate_conn(conn)
  File "C:\My_programms\JetBrains\PyCharm Community Edition 2023.3.2\My_programms\tg_voise\.venv\Lib\site-packages\urllib3\connectionpool.py", line 1099, in _validate_conn
    conn.connect()
  File "C:\My_programms\JetBrains\PyCharm Community Edition 2023.3.2\My_programms\tg_voise\.venv\Lib\site-packages\urllib3\connection.py", line 616, in connect
    self.sock = sock = self._new_conn()
                       ^^^^^^^^^^^^^^^^
  File "C:\My_programms\JetBrains\PyCharm Community Edition 2023.3.2\My_programms\tg_voise\.venv\Lib\site-packages\urllib3\connection.py", line 205, in _new_conn
    raise NameResolutionError(self.host, self, e) from e
urllib3.exceptions.NameResolutionError: <urllib3.connection.HTTPSConnection object at 0x0000018DBC43ED80>: Failed to resolve 'api.telegram.org' ([Errno 11001] getaddrinfo failed)

The above exception was the direct cause of the following exception:

Traceback (most recent call last):
  File "C:\My_programms\JetBrains\PyCharm Community Edition 2023.3.2\My_programms\tg_voise\.venv\Lib\site-packages\requests\adapters.py", line 486, in send
    resp = conn.urlopen(
           ^^^^^^^^^^^^^
  File "C:\My_programms\JetBrains\PyCharm Community Edition 2023.3.2\My_programms\tg_voise\.venv\Lib\site-packages\urllib3\connectionpool.py", line 847, in urlopen
    retries = retries.increment(
              ^^^^^^^^^^^^^^^^^^
  File "C:\My_programms\JetBrains\PyCharm Community Edition 2023.3.2\My_programms\tg_voise\.venv\Lib\site-packages\urllib3\util\retry.py", line 515, in increment
    raise MaxRetryError(_pool, url, reason) from reason  # type: ignore[arg-type]
    ^^^^^^^^^^^^^^^^^^^^^^^^^^^^^^^^^^^^^^^^^^^^^^^^^^^
urllib3.exceptions.MaxRetryError: HTTPSConnectionPool(host='api.telegram.org', port=443): Max retries exceeded with url: /bot6565406578:AAHJXXP9C3YuGGrZavTnkhlJTq4hQl1V3KE/getUpdates?offset=585466214&timeout=20 (Caused by NameResolutionError("<urllib3.connection.HTTPSConnection object at 0x0000018DBC43ED80>: Failed to resolve 'api.telegram.org' ([Errno 11001] getaddrinfo failed)"))

During handling of the above exception, another exception occurred:

Traceback (most recent call last):
  File "C:\My_programms\JetBrains\PyCharm Community Edition 2023.3.2\My_programms\tg_voise\.venv\Lib\site-packages\telebot\__init__.py", line 1081, in infinity_polling
    self.polling(non_stop=True, timeout=timeout, long_polling_timeout=long_polling_timeout,
  File "C:\My_programms\JetBrains\PyCharm Community Edition 2023.3.2\My_programms\tg_voise\.venv\Lib\site-packages\telebot\__init__.py", line 1169, in polling
    self.__threaded_polling(non_stop=non_stop, interval=interval, timeout=timeout, long_polling_timeout=long_polling_timeout,
  File "C:\My_programms\JetBrains\PyCharm Community Edition 2023.3.2\My_programms\tg_voise\.venv\Lib\site-packages\telebot\__init__.py", line 1244, in __threaded_polling
    raise e
  File "C:\My_programms\JetBrains\PyCharm Community Edition 2023.3.2\My_programms\tg_voise\.venv\Lib\site-packages\telebot\__init__.py", line 1205, in __threaded_polling
    polling_thread.raise_exceptions()
  File "C:\My_programms\JetBrains\PyCharm Community Edition 2023.3.2\My_programms\tg_voise\.venv\Lib\site-packages\telebot\util.py", line 111, in raise_exceptions
    raise self.exception_info
  File "C:\My_programms\JetBrains\PyCharm Community Edition 2023.3.2\My_programms\tg_voise\.venv\Lib\site-packages\telebot\util.py", line 93, in run
    task(*args, **kwargs)
  File "C:\My_programms\JetBrains\PyCharm Community Edition 2023.3.2\My_programms\tg_voise\.venv\Lib\site-packages\telebot\__init__.py", line 675, in __retrieve_updates
    updates = self.get_updates(offset=(self.last_update_id + 1),
             ^^^^^^^^^^^^^^^^^^^^^^^^^^^^^^^^^^^^^^^^^^^^^^^^^^
  File "C:\My_programms\JetBrains\PyCharm Community Edition 2023.3.2\My_programms\tg_voise\.venv\Lib\site-packages\telebot\__init__.py", line 647, in get_updates
    json_updates = apihelper.get_updates(
                   ^^^^^^^^^^^^^^^^^^^^^^
  File "C:\My_programms\JetBrains\PyCharm Community Edition 2023.3.2\My_programms\tg_voise\.venv\Lib\site-packages\telebot\apihelper.py", line 327, in get_updates
    return _make_request(token, method_url, params=payload)
           ^^^^^^^^^^^^^^^^^^^^^^^^^^^^^^^^^^^^^^^^^^^^^^^^
  File "C:\My_programms\JetBrains\PyCharm Community Edition 2023.3.2\My_programms\tg_voise\.venv\Lib\site-packages\telebot\apihelper.py", line 161, in _make_request
    result = _get_req_session().request(
             ^^^^^^^^^^^^^^^^^^^^^^^^^^^
  File "C:\My_programms\JetBrains\PyCharm Community Edition 2023.3.2\My_programms\tg_voise\.venv\Lib\site-packages\requests\sessions.py", line 589, in request
    resp = self.send(prep, **send_kwargs)
           ^^^^^^^^^^^^^^^^^^^^^^^^^^^^^^
  File "C:\My_programms\JetBrains\PyCharm Community Edition 2023.3.2\My_programms\tg_voise\.venv\Lib\site-packages\requests\sessions.py", line 703, in send
    r = adapter.send(request, **kwargs)
        ^^^^^^^^^^^^^^^^^^^^^^^^^^^^^^^
  File "C:\My_programms\JetBrains\PyCharm Community Edition 2023.3.2\My_programms\tg_voise\.venv\Lib\site-packages\requests\adapters.py", line 519, in send
    raise ConnectionError(e, request=request)
requests.exceptions.ConnectionError: HTTPSConnectionPool(host='api.telegram.org', port=443): Max retries exceeded with url: /bot6565406578:AAHJXXP9C3YuGGrZavTnkhlJTq4hQl1V3KE/getUpdates?offset=585466214&timeout=20 (Caused by NameResolutionError("<urllib3.connection.HTTPSConnection object at 0x0000018DBC43ED80>: Failed to resolve 'api.telegram.org' ([Errno 11001] getaddrinfo failed)"))

2024-04-12 23:37:16,832 - TeleBot - ERROR - Infinity polling exception: HTTPSConnectionPool(host='api.telegram.org', port=443): Max retries exceeded with url: /bot6565406578:AAHJXXP9C3YuGGrZavTnkhlJTq4hQl1V3KE/getUpdates?offset=585466214&timeout=20 (Caused by NameResolutionError("<urllib3.connection.HTTPSConnection object at 0x0000018DBCE3C8F0>: Failed to resolve 'api.telegram.org' ([Errno 11001] getaddrinfo failed)"))
2024-04-12 23:37:16,838 - TeleBot - ERROR - Exception traceback:
Traceback (most recent call last):
  File "C:\My_programms\JetBrains\PyCharm Community Edition 2023.3.2\My_programms\tg_voise\.venv\Lib\site-packages\urllib3\connection.py", line 198, in _new_conn
    sock = connection.create_connection(
           ^^^^^^^^^^^^^^^^^^^^^^^^^^^^^
  File "C:\My_programms\JetBrains\PyCharm Community Edition 2023.3.2\My_programms\tg_voise\.venv\Lib\site-packages\urllib3\util\connection.py", line 60, in create_connection
    for res in socket.getaddrinfo(host, port, family, socket.SOCK_STREAM):
               ^^^^^^^^^^^^^^^^^^^^^^^^^^^^^^^^^^^^^^^^^^^^^^^^^^^^^^^^^^
  File "C:\Users\Asus\AppData\Local\Programs\Python\Python312\Lib\socket.py", line 963, in getaddrinfo
    for res in _socket.getaddrinfo(host, port, family, type, proto, flags):
               ^^^^^^^^^^^^^^^^^^^^^^^^^^^^^^^^^^^^^^^^^^^^^^^^^^^^^^^^^^^
socket.gaierror: [Errno 11001] getaddrinfo failed

The above exception was the direct cause of the following exception:

Traceback (most recent call last):
  File "C:\My_programms\JetBrains\PyCharm Community Edition 2023.3.2\My_programms\tg_voise\.venv\Lib\site-packages\urllib3\connectionpool.py", line 793, in urlopen
    response = self._make_request(
               ^^^^^^^^^^^^^^^^^^^
  File "C:\My_programms\JetBrains\PyCharm Community Edition 2023.3.2\My_programms\tg_voise\.venv\Lib\site-packages\urllib3\connectionpool.py", line 491, in _make_request
    raise new_e
  File "C:\My_programms\JetBrains\PyCharm Community Edition 2023.3.2\My_programms\tg_voise\.venv\Lib\site-packages\urllib3\connectionpool.py", line 467, in _make_request
    self._validate_conn(conn)
  File "C:\My_programms\JetBrains\PyCharm Community Edition 2023.3.2\My_programms\tg_voise\.venv\Lib\site-packages\urllib3\connectionpool.py", line 1099, in _validate_conn
    conn.connect()
  File "C:\My_programms\JetBrains\PyCharm Community Edition 2023.3.2\My_programms\tg_voise\.venv\Lib\site-packages\urllib3\connection.py", line 616, in connect
    self.sock = sock = self._new_conn()
                       ^^^^^^^^^^^^^^^^
  File "C:\My_programms\JetBrains\PyCharm Community Edition 2023.3.2\My_programms\tg_voise\.venv\Lib\site-packages\urllib3\connection.py", line 205, in _new_conn
    raise NameResolutionError(self.host, self, e) from e
urllib3.exceptions.NameResolutionError: <urllib3.connection.HTTPSConnection object at 0x0000018DBCE3C8F0>: Failed to resolve 'api.telegram.org' ([Errno 11001] getaddrinfo failed)

The above exception was the direct cause of the following exception:

Traceback (most recent call last):
  File "C:\My_programms\JetBrains\PyCharm Community Edition 2023.3.2\My_programms\tg_voise\.venv\Lib\site-packages\requests\adapters.py", line 486, in send
    resp = conn.urlopen(
           ^^^^^^^^^^^^^
  File "C:\My_programms\JetBrains\PyCharm Community Edition 2023.3.2\My_programms\tg_voise\.venv\Lib\site-packages\urllib3\connectionpool.py", line 847, in urlopen
    retries = retries.increment(
              ^^^^^^^^^^^^^^^^^^
  File "C:\My_programms\JetBrains\PyCharm Community Edition 2023.3.2\My_programms\tg_voise\.venv\Lib\site-packages\urllib3\util\retry.py", line 515, in increment
    raise MaxRetryError(_pool, url, reason) from reason  # type: ignore[arg-type]
    ^^^^^^^^^^^^^^^^^^^^^^^^^^^^^^^^^^^^^^^^^^^^^^^^^^^
urllib3.exceptions.MaxRetryError: HTTPSConnectionPool(host='api.telegram.org', port=443): Max retries exceeded with url: /bot6565406578:AAHJXXP9C3YuGGrZavTnkhlJTq4hQl1V3KE/getUpdates?offset=585466214&timeout=20 (Caused by NameResolutionError("<urllib3.connection.HTTPSConnection object at 0x0000018DBCE3C8F0>: Failed to resolve 'api.telegram.org' ([Errno 11001] getaddrinfo failed)"))

During handling of the above exception, another exception occurred:

Traceback (most recent call last):
  File "C:\My_programms\JetBrains\PyCharm Community Edition 2023.3.2\My_programms\tg_voise\.venv\Lib\site-packages\telebot\__init__.py", line 1081, in infinity_polling
    self.polling(non_stop=True, timeout=timeout, long_polling_timeout=long_polling_timeout,
  File "C:\My_programms\JetBrains\PyCharm Community Edition 2023.3.2\My_programms\tg_voise\.venv\Lib\site-packages\telebot\__init__.py", line 1169, in polling
    self.__threaded_polling(non_stop=non_stop, interval=interval, timeout=timeout, long_polling_timeout=long_polling_timeout,
  File "C:\My_programms\JetBrains\PyCharm Community Edition 2023.3.2\My_programms\tg_voise\.venv\Lib\site-packages\telebot\__init__.py", line 1244, in __threaded_polling
    raise e
  File "C:\My_programms\JetBrains\PyCharm Community Edition 2023.3.2\My_programms\tg_voise\.venv\Lib\site-packages\telebot\__init__.py", line 1205, in __threaded_polling
    polling_thread.raise_exceptions()
  File "C:\My_programms\JetBrains\PyCharm Community Edition 2023.3.2\My_programms\tg_voise\.venv\Lib\site-packages\telebot\util.py", line 111, in raise_exceptions
    raise self.exception_info
  File "C:\My_programms\JetBrains\PyCharm Community Edition 2023.3.2\My_programms\tg_voise\.venv\Lib\site-packages\telebot\util.py", line 93, in run
    task(*args, **kwargs)
  File "C:\My_programms\JetBrains\PyCharm Community Edition 2023.3.2\My_programms\tg_voise\.venv\Lib\site-packages\telebot\__init__.py", line 675, in __retrieve_updates
    updates = self.get_updates(offset=(self.last_update_id + 1),
             ^^^^^^^^^^^^^^^^^^^^^^^^^^^^^^^^^^^^^^^^^^^^^^^^^^
  File "C:\My_programms\JetBrains\PyCharm Community Edition 2023.3.2\My_programms\tg_voise\.venv\Lib\site-packages\telebot\__init__.py", line 647, in get_updates
    json_updates = apihelper.get_updates(
                   ^^^^^^^^^^^^^^^^^^^^^^
  File "C:\My_programms\JetBrains\PyCharm Community Edition 2023.3.2\My_programms\tg_voise\.venv\Lib\site-packages\telebot\apihelper.py", line 327, in get_updates
    return _make_request(token, method_url, params=payload)
           ^^^^^^^^^^^^^^^^^^^^^^^^^^^^^^^^^^^^^^^^^^^^^^^^
  File "C:\My_programms\JetBrains\PyCharm Community Edition 2023.3.2\My_programms\tg_voise\.venv\Lib\site-packages\telebot\apihelper.py", line 161, in _make_request
    result = _get_req_session().request(
             ^^^^^^^^^^^^^^^^^^^^^^^^^^^
  File "C:\My_programms\JetBrains\PyCharm Community Edition 2023.3.2\My_programms\tg_voise\.venv\Lib\site-packages\requests\sessions.py", line 589, in request
    resp = self.send(prep, **send_kwargs)
           ^^^^^^^^^^^^^^^^^^^^^^^^^^^^^^
  File "C:\My_programms\JetBrains\PyCharm Community Edition 2023.3.2\My_programms\tg_voise\.venv\Lib\site-packages\requests\sessions.py", line 703, in send
    r = adapter.send(request, **kwargs)
        ^^^^^^^^^^^^^^^^^^^^^^^^^^^^^^^
  File "C:\My_programms\JetBrains\PyCharm Community Edition 2023.3.2\My_programms\tg_voise\.venv\Lib\site-packages\requests\adapters.py", line 519, in send
    raise ConnectionError(e, request=request)
requests.exceptions.ConnectionError: HTTPSConnectionPool(host='api.telegram.org', port=443): Max retries exceeded with url: /bot6565406578:AAHJXXP9C3YuGGrZavTnkhlJTq4hQl1V3KE/getUpdates?offset=585466214&timeout=20 (Caused by NameResolutionError("<urllib3.connection.HTTPSConnection object at 0x0000018DBCE3C8F0>: Failed to resolve 'api.telegram.org' ([Errno 11001] getaddrinfo failed)"))

2024-04-12 23:37:19,857 - TeleBot - ERROR - Infinity polling exception: HTTPSConnectionPool(host='api.telegram.org', port=443): Max retries exceeded with url: /bot6565406578:AAHJXXP9C3YuGGrZavTnkhlJTq4hQl1V3KE/getUpdates?offset=585466214&timeout=20 (Caused by NameResolutionError("<urllib3.connection.HTTPSConnection object at 0x0000018DBCE3F770>: Failed to resolve 'api.telegram.org' ([Errno 11001] getaddrinfo failed)"))
2024-04-12 23:37:19,860 - TeleBot - ERROR - Exception traceback:
Traceback (most recent call last):
  File "C:\My_programms\JetBrains\PyCharm Community Edition 2023.3.2\My_programms\tg_voise\.venv\Lib\site-packages\urllib3\connection.py", line 198, in _new_conn
    sock = connection.create_connection(
           ^^^^^^^^^^^^^^^^^^^^^^^^^^^^^
  File "C:\My_programms\JetBrains\PyCharm Community Edition 2023.3.2\My_programms\tg_voise\.venv\Lib\site-packages\urllib3\util\connection.py", line 60, in create_connection
    for res in socket.getaddrinfo(host, port, family, socket.SOCK_STREAM):
               ^^^^^^^^^^^^^^^^^^^^^^^^^^^^^^^^^^^^^^^^^^^^^^^^^^^^^^^^^^
  File "C:\Users\Asus\AppData\Local\Programs\Python\Python312\Lib\socket.py", line 963, in getaddrinfo
    for res in _socket.getaddrinfo(host, port, family, type, proto, flags):
               ^^^^^^^^^^^^^^^^^^^^^^^^^^^^^^^^^^^^^^^^^^^^^^^^^^^^^^^^^^^
socket.gaierror: [Errno 11001] getaddrinfo failed

The above exception was the direct cause of the following exception:

Traceback (most recent call last):
  File "C:\My_programms\JetBrains\PyCharm Community Edition 2023.3.2\My_programms\tg_voise\.venv\Lib\site-packages\urllib3\connectionpool.py", line 793, in urlopen
    response = self._make_request(
               ^^^^^^^^^^^^^^^^^^^
  File "C:\My_programms\JetBrains\PyCharm Community Edition 2023.3.2\My_programms\tg_voise\.venv\Lib\site-packages\urllib3\connectionpool.py", line 491, in _make_request
    raise new_e
  File "C:\My_programms\JetBrains\PyCharm Community Edition 2023.3.2\My_programms\tg_voise\.venv\Lib\site-packages\urllib3\connectionpool.py", line 467, in _make_request
    self._validate_conn(conn)
  File "C:\My_programms\JetBrains\PyCharm Community Edition 2023.3.2\My_programms\tg_voise\.venv\Lib\site-packages\urllib3\connectionpool.py", line 1099, in _validate_conn
    conn.connect()
  File "C:\My_programms\JetBrains\PyCharm Community Edition 2023.3.2\My_programms\tg_voise\.venv\Lib\site-packages\urllib3\connection.py", line 616, in connect
    self.sock = sock = self._new_conn()
                       ^^^^^^^^^^^^^^^^
  File "C:\My_programms\JetBrains\PyCharm Community Edition 2023.3.2\My_programms\tg_voise\.venv\Lib\site-packages\urllib3\connection.py", line 205, in _new_conn
    raise NameResolutionError(self.host, self, e) from e
urllib3.exceptions.NameResolutionError: <urllib3.connection.HTTPSConnection object at 0x0000018DBCE3F770>: Failed to resolve 'api.telegram.org' ([Errno 11001] getaddrinfo failed)

The above exception was the direct cause of the following exception:

Traceback (most recent call last):
  File "C:\My_programms\JetBrains\PyCharm Community Edition 2023.3.2\My_programms\tg_voise\.venv\Lib\site-packages\requests\adapters.py", line 486, in send
    resp = conn.urlopen(
           ^^^^^^^^^^^^^
  File "C:\My_programms\JetBrains\PyCharm Community Edition 2023.3.2\My_programms\tg_voise\.venv\Lib\site-packages\urllib3\connectionpool.py", line 847, in urlopen
    retries = retries.increment(
              ^^^^^^^^^^^^^^^^^^
  File "C:\My_programms\JetBrains\PyCharm Community Edition 2023.3.2\My_programms\tg_voise\.venv\Lib\site-packages\urllib3\util\retry.py", line 515, in increment
    raise MaxRetryError(_pool, url, reason) from reason  # type: ignore[arg-type]
    ^^^^^^^^^^^^^^^^^^^^^^^^^^^^^^^^^^^^^^^^^^^^^^^^^^^
urllib3.exceptions.MaxRetryError: HTTPSConnectionPool(host='api.telegram.org', port=443): Max retries exceeded with url: /bot6565406578:AAHJXXP9C3YuGGrZavTnkhlJTq4hQl1V3KE/getUpdates?offset=585466214&timeout=20 (Caused by NameResolutionError("<urllib3.connection.HTTPSConnection object at 0x0000018DBCE3F770>: Failed to resolve 'api.telegram.org' ([Errno 11001] getaddrinfo failed)"))

During handling of the above exception, another exception occurred:

Traceback (most recent call last):
  File "C:\My_programms\JetBrains\PyCharm Community Edition 2023.3.2\My_programms\tg_voise\.venv\Lib\site-packages\telebot\__init__.py", line 1081, in infinity_polling
    self.polling(non_stop=True, timeout=timeout, long_polling_timeout=long_polling_timeout,
  File "C:\My_programms\JetBrains\PyCharm Community Edition 2023.3.2\My_programms\tg_voise\.venv\Lib\site-packages\telebot\__init__.py", line 1169, in polling
    self.__threaded_polling(non_stop=non_stop, interval=interval, timeout=timeout, long_polling_timeout=long_polling_timeout,
  File "C:\My_programms\JetBrains\PyCharm Community Edition 2023.3.2\My_programms\tg_voise\.venv\Lib\site-packages\telebot\__init__.py", line 1244, in __threaded_polling
    raise e
  File "C:\My_programms\JetBrains\PyCharm Community Edition 2023.3.2\My_programms\tg_voise\.venv\Lib\site-packages\telebot\__init__.py", line 1205, in __threaded_polling
    polling_thread.raise_exceptions()
  File "C:\My_programms\JetBrains\PyCharm Community Edition 2023.3.2\My_programms\tg_voise\.venv\Lib\site-packages\telebot\util.py", line 111, in raise_exceptions
    raise self.exception_info
  File "C:\My_programms\JetBrains\PyCharm Community Edition 2023.3.2\My_programms\tg_voise\.venv\Lib\site-packages\telebot\util.py", line 93, in run
    task(*args, **kwargs)
  File "C:\My_programms\JetBrains\PyCharm Community Edition 2023.3.2\My_programms\tg_voise\.venv\Lib\site-packages\telebot\__init__.py", line 675, in __retrieve_updates
    updates = self.get_updates(offset=(self.last_update_id + 1),
             ^^^^^^^^^^^^^^^^^^^^^^^^^^^^^^^^^^^^^^^^^^^^^^^^^^
  File "C:\My_programms\JetBrains\PyCharm Community Edition 2023.3.2\My_programms\tg_voise\.venv\Lib\site-packages\telebot\__init__.py", line 647, in get_updates
    json_updates = apihelper.get_updates(
                   ^^^^^^^^^^^^^^^^^^^^^^
  File "C:\My_programms\JetBrains\PyCharm Community Edition 2023.3.2\My_programms\tg_voise\.venv\Lib\site-packages\telebot\apihelper.py", line 327, in get_updates
    return _make_request(token, method_url, params=payload)
           ^^^^^^^^^^^^^^^^^^^^^^^^^^^^^^^^^^^^^^^^^^^^^^^^
  File "C:\My_programms\JetBrains\PyCharm Community Edition 2023.3.2\My_programms\tg_voise\.venv\Lib\site-packages\telebot\apihelper.py", line 161, in _make_request
    result = _get_req_session().request(
             ^^^^^^^^^^^^^^^^^^^^^^^^^^^
  File "C:\My_programms\JetBrains\PyCharm Community Edition 2023.3.2\My_programms\tg_voise\.venv\Lib\site-packages\requests\sessions.py", line 589, in request
    resp = self.send(prep, **send_kwargs)
           ^^^^^^^^^^^^^^^^^^^^^^^^^^^^^^
  File "C:\My_programms\JetBrains\PyCharm Community Edition 2023.3.2\My_programms\tg_voise\.venv\Lib\site-packages\requests\sessions.py", line 703, in send
    r = adapter.send(request, **kwargs)
        ^^^^^^^^^^^^^^^^^^^^^^^^^^^^^^^
  File "C:\My_programms\JetBrains\PyCharm Community Edition 2023.3.2\My_programms\tg_voise\.venv\Lib\site-packages\requests\adapters.py", line 519, in send
    raise ConnectionError(e, request=request)
requests.exceptions.ConnectionError: HTTPSConnectionPool(host='api.telegram.org', port=443): Max retries exceeded with url: /bot6565406578:AAHJXXP9C3YuGGrZavTnkhlJTq4hQl1V3KE/getUpdates?offset=585466214&timeout=20 (Caused by NameResolutionError("<urllib3.connection.HTTPSConnection object at 0x0000018DBCE3F770>: Failed to resolve 'api.telegram.org' ([Errno 11001] getaddrinfo failed)"))

2024-04-12 23:37:22,880 - TeleBot - ERROR - Infinity polling exception: HTTPSConnectionPool(host='api.telegram.org', port=443): Max retries exceeded with url: /bot6565406578:AAHJXXP9C3YuGGrZavTnkhlJTq4hQl1V3KE/getUpdates?offset=585466214&timeout=20 (Caused by NameResolutionError("<urllib3.connection.HTTPSConnection object at 0x0000018DBBF64F20>: Failed to resolve 'api.telegram.org' ([Errno 11001] getaddrinfo failed)"))
2024-04-12 23:37:22,884 - TeleBot - ERROR - Exception traceback:
Traceback (most recent call last):
  File "C:\My_programms\JetBrains\PyCharm Community Edition 2023.3.2\My_programms\tg_voise\.venv\Lib\site-packages\urllib3\connection.py", line 198, in _new_conn
    sock = connection.create_connection(
           ^^^^^^^^^^^^^^^^^^^^^^^^^^^^^
  File "C:\My_programms\JetBrains\PyCharm Community Edition 2023.3.2\My_programms\tg_voise\.venv\Lib\site-packages\urllib3\util\connection.py", line 60, in create_connection
    for res in socket.getaddrinfo(host, port, family, socket.SOCK_STREAM):
               ^^^^^^^^^^^^^^^^^^^^^^^^^^^^^^^^^^^^^^^^^^^^^^^^^^^^^^^^^^
  File "C:\Users\Asus\AppData\Local\Programs\Python\Python312\Lib\socket.py", line 963, in getaddrinfo
    for res in _socket.getaddrinfo(host, port, family, type, proto, flags):
               ^^^^^^^^^^^^^^^^^^^^^^^^^^^^^^^^^^^^^^^^^^^^^^^^^^^^^^^^^^^
socket.gaierror: [Errno 11001] getaddrinfo failed

The above exception was the direct cause of the following exception:

Traceback (most recent call last):
  File "C:\My_programms\JetBrains\PyCharm Community Edition 2023.3.2\My_programms\tg_voise\.venv\Lib\site-packages\urllib3\connectionpool.py", line 793, in urlopen
    response = self._make_request(
               ^^^^^^^^^^^^^^^^^^^
  File "C:\My_programms\JetBrains\PyCharm Community Edition 2023.3.2\My_programms\tg_voise\.venv\Lib\site-packages\urllib3\connectionpool.py", line 491, in _make_request
    raise new_e
  File "C:\My_programms\JetBrains\PyCharm Community Edition 2023.3.2\My_programms\tg_voise\.venv\Lib\site-packages\urllib3\connectionpool.py", line 467, in _make_request
    self._validate_conn(conn)
  File "C:\My_programms\JetBrains\PyCharm Community Edition 2023.3.2\My_programms\tg_voise\.venv\Lib\site-packages\urllib3\connectionpool.py", line 1099, in _validate_conn
    conn.connect()
  File "C:\My_programms\JetBrains\PyCharm Community Edition 2023.3.2\My_programms\tg_voise\.venv\Lib\site-packages\urllib3\connection.py", line 616, in connect
    self.sock = sock = self._new_conn()
                       ^^^^^^^^^^^^^^^^
  File "C:\My_programms\JetBrains\PyCharm Community Edition 2023.3.2\My_programms\tg_voise\.venv\Lib\site-packages\urllib3\connection.py", line 205, in _new_conn
    raise NameResolutionError(self.host, self, e) from e
urllib3.exceptions.NameResolutionError: <urllib3.connection.HTTPSConnection object at 0x0000018DBBF64F20>: Failed to resolve 'api.telegram.org' ([Errno 11001] getaddrinfo failed)

The above exception was the direct cause of the following exception:

Traceback (most recent call last):
  File "C:\My_programms\JetBrains\PyCharm Community Edition 2023.3.2\My_programms\tg_voise\.venv\Lib\site-packages\requests\adapters.py", line 486, in send
    resp = conn.urlopen(
           ^^^^^^^^^^^^^
  File "C:\My_programms\JetBrains\PyCharm Community Edition 2023.3.2\My_programms\tg_voise\.venv\Lib\site-packages\urllib3\connectionpool.py", line 847, in urlopen
    retries = retries.increment(
              ^^^^^^^^^^^^^^^^^^
  File "C:\My_programms\JetBrains\PyCharm Community Edition 2023.3.2\My_programms\tg_voise\.venv\Lib\site-packages\urllib3\util\retry.py", line 515, in increment
    raise MaxRetryError(_pool, url, reason) from reason  # type: ignore[arg-type]
    ^^^^^^^^^^^^^^^^^^^^^^^^^^^^^^^^^^^^^^^^^^^^^^^^^^^
urllib3.exceptions.MaxRetryError: HTTPSConnectionPool(host='api.telegram.org', port=443): Max retries exceeded with url: /bot6565406578:AAHJXXP9C3YuGGrZavTnkhlJTq4hQl1V3KE/getUpdates?offset=585466214&timeout=20 (Caused by NameResolutionError("<urllib3.connection.HTTPSConnection object at 0x0000018DBBF64F20>: Failed to resolve 'api.telegram.org' ([Errno 11001] getaddrinfo failed)"))

During handling of the above exception, another exception occurred:

Traceback (most recent call last):
  File "C:\My_programms\JetBrains\PyCharm Community Edition 2023.3.2\My_programms\tg_voise\.venv\Lib\site-packages\telebot\__init__.py", line 1081, in infinity_polling
    self.polling(non_stop=True, timeout=timeout, long_polling_timeout=long_polling_timeout,
  File "C:\My_programms\JetBrains\PyCharm Community Edition 2023.3.2\My_programms\tg_voise\.venv\Lib\site-packages\telebot\__init__.py", line 1169, in polling
    self.__threaded_polling(non_stop=non_stop, interval=interval, timeout=timeout, long_polling_timeout=long_polling_timeout,
  File "C:\My_programms\JetBrains\PyCharm Community Edition 2023.3.2\My_programms\tg_voise\.venv\Lib\site-packages\telebot\__init__.py", line 1244, in __threaded_polling
    raise e
  File "C:\My_programms\JetBrains\PyCharm Community Edition 2023.3.2\My_programms\tg_voise\.venv\Lib\site-packages\telebot\__init__.py", line 1205, in __threaded_polling
    polling_thread.raise_exceptions()
  File "C:\My_programms\JetBrains\PyCharm Community Edition 2023.3.2\My_programms\tg_voise\.venv\Lib\site-packages\telebot\util.py", line 111, in raise_exceptions
    raise self.exception_info
  File "C:\My_programms\JetBrains\PyCharm Community Edition 2023.3.2\My_programms\tg_voise\.venv\Lib\site-packages\telebot\util.py", line 93, in run
    task(*args, **kwargs)
  File "C:\My_programms\JetBrains\PyCharm Community Edition 2023.3.2\My_programms\tg_voise\.venv\Lib\site-packages\telebot\__init__.py", line 675, in __retrieve_updates
    updates = self.get_updates(offset=(self.last_update_id + 1),
             ^^^^^^^^^^^^^^^^^^^^^^^^^^^^^^^^^^^^^^^^^^^^^^^^^^
  File "C:\My_programms\JetBrains\PyCharm Community Edition 2023.3.2\My_programms\tg_voise\.venv\Lib\site-packages\telebot\__init__.py", line 647, in get_updates
    json_updates = apihelper.get_updates(
                   ^^^^^^^^^^^^^^^^^^^^^^
  File "C:\My_programms\JetBrains\PyCharm Community Edition 2023.3.2\My_programms\tg_voise\.venv\Lib\site-packages\telebot\apihelper.py", line 327, in get_updates
    return _make_request(token, method_url, params=payload)
           ^^^^^^^^^^^^^^^^^^^^^^^^^^^^^^^^^^^^^^^^^^^^^^^^
  File "C:\My_programms\JetBrains\PyCharm Community Edition 2023.3.2\My_programms\tg_voise\.venv\Lib\site-packages\telebot\apihelper.py", line 161, in _make_request
    result = _get_req_session().request(
             ^^^^^^^^^^^^^^^^^^^^^^^^^^^
  File "C:\My_programms\JetBrains\PyCharm Community Edition 2023.3.2\My_programms\tg_voise\.venv\Lib\site-packages\requests\sessions.py", line 589, in request
    resp = self.send(prep, **send_kwargs)
           ^^^^^^^^^^^^^^^^^^^^^^^^^^^^^^
  File "C:\My_programms\JetBrains\PyCharm Community Edition 2023.3.2\My_programms\tg_voise\.venv\Lib\site-packages\requests\sessions.py", line 703, in send
    r = adapter.send(request, **kwargs)
        ^^^^^^^^^^^^^^^^^^^^^^^^^^^^^^^
  File "C:\My_programms\JetBrains\PyCharm Community Edition 2023.3.2\My_programms\tg_voise\.venv\Lib\site-packages\requests\adapters.py", line 519, in send
    raise ConnectionError(e, request=request)
requests.exceptions.ConnectionError: HTTPSConnectionPool(host='api.telegram.org', port=443): Max retries exceeded with url: /bot6565406578:AAHJXXP9C3YuGGrZavTnkhlJTq4hQl1V3KE/getUpdates?offset=585466214&timeout=20 (Caused by NameResolutionError("<urllib3.connection.HTTPSConnection object at 0x0000018DBBF64F20>: Failed to resolve 'api.telegram.org' ([Errno 11001] getaddrinfo failed)"))

2024-04-12 23:37:25,909 - TeleBot - ERROR - Infinity polling exception: HTTPSConnectionPool(host='api.telegram.org', port=443): Max retries exceeded with url: /bot6565406578:AAHJXXP9C3YuGGrZavTnkhlJTq4hQl1V3KE/getUpdates?offset=585466214&timeout=20 (Caused by NameResolutionError("<urllib3.connection.HTTPSConnection object at 0x0000018DBCE3C8C0>: Failed to resolve 'api.telegram.org' ([Errno 11001] getaddrinfo failed)"))
2024-04-12 23:37:25,912 - TeleBot - ERROR - Exception traceback:
Traceback (most recent call last):
  File "C:\My_programms\JetBrains\PyCharm Community Edition 2023.3.2\My_programms\tg_voise\.venv\Lib\site-packages\urllib3\connection.py", line 198, in _new_conn
    sock = connection.create_connection(
           ^^^^^^^^^^^^^^^^^^^^^^^^^^^^^
  File "C:\My_programms\JetBrains\PyCharm Community Edition 2023.3.2\My_programms\tg_voise\.venv\Lib\site-packages\urllib3\util\connection.py", line 60, in create_connection
    for res in socket.getaddrinfo(host, port, family, socket.SOCK_STREAM):
               ^^^^^^^^^^^^^^^^^^^^^^^^^^^^^^^^^^^^^^^^^^^^^^^^^^^^^^^^^^
  File "C:\Users\Asus\AppData\Local\Programs\Python\Python312\Lib\socket.py", line 963, in getaddrinfo
    for res in _socket.getaddrinfo(host, port, family, type, proto, flags):
               ^^^^^^^^^^^^^^^^^^^^^^^^^^^^^^^^^^^^^^^^^^^^^^^^^^^^^^^^^^^
socket.gaierror: [Errno 11001] getaddrinfo failed

The above exception was the direct cause of the following exception:

Traceback (most recent call last):
  File "C:\My_programms\JetBrains\PyCharm Community Edition 2023.3.2\My_programms\tg_voise\.venv\Lib\site-packages\urllib3\connectionpool.py", line 793, in urlopen
    response = self._make_request(
               ^^^^^^^^^^^^^^^^^^^
  File "C:\My_programms\JetBrains\PyCharm Community Edition 2023.3.2\My_programms\tg_voise\.venv\Lib\site-packages\urllib3\connectionpool.py", line 491, in _make_request
    raise new_e
  File "C:\My_programms\JetBrains\PyCharm Community Edition 2023.3.2\My_programms\tg_voise\.venv\Lib\site-packages\urllib3\connectionpool.py", line 467, in _make_request
    self._validate_conn(conn)
  File "C:\My_programms\JetBrains\PyCharm Community Edition 2023.3.2\My_programms\tg_voise\.venv\Lib\site-packages\urllib3\connectionpool.py", line 1099, in _validate_conn
    conn.connect()
  File "C:\My_programms\JetBrains\PyCharm Community Edition 2023.3.2\My_programms\tg_voise\.venv\Lib\site-packages\urllib3\connection.py", line 616, in connect
    self.sock = sock = self._new_conn()
                       ^^^^^^^^^^^^^^^^
  File "C:\My_programms\JetBrains\PyCharm Community Edition 2023.3.2\My_programms\tg_voise\.venv\Lib\site-packages\urllib3\connection.py", line 205, in _new_conn
    raise NameResolutionError(self.host, self, e) from e
urllib3.exceptions.NameResolutionError: <urllib3.connection.HTTPSConnection object at 0x0000018DBCE3C8C0>: Failed to resolve 'api.telegram.org' ([Errno 11001] getaddrinfo failed)

The above exception was the direct cause of the following exception:

Traceback (most recent call last):
  File "C:\My_programms\JetBrains\PyCharm Community Edition 2023.3.2\My_programms\tg_voise\.venv\Lib\site-packages\requests\adapters.py", line 486, in send
    resp = conn.urlopen(
           ^^^^^^^^^^^^^
  File "C:\My_programms\JetBrains\PyCharm Community Edition 2023.3.2\My_programms\tg_voise\.venv\Lib\site-packages\urllib3\connectionpool.py", line 847, in urlopen
    retries = retries.increment(
              ^^^^^^^^^^^^^^^^^^
  File "C:\My_programms\JetBrains\PyCharm Community Edition 2023.3.2\My_programms\tg_voise\.venv\Lib\site-packages\urllib3\util\retry.py", line 515, in increment
    raise MaxRetryError(_pool, url, reason) from reason  # type: ignore[arg-type]
    ^^^^^^^^^^^^^^^^^^^^^^^^^^^^^^^^^^^^^^^^^^^^^^^^^^^
urllib3.exceptions.MaxRetryError: HTTPSConnectionPool(host='api.telegram.org', port=443): Max retries exceeded with url: /bot6565406578:AAHJXXP9C3YuGGrZavTnkhlJTq4hQl1V3KE/getUpdates?offset=585466214&timeout=20 (Caused by NameResolutionError("<urllib3.connection.HTTPSConnection object at 0x0000018DBCE3C8C0>: Failed to resolve 'api.telegram.org' ([Errno 11001] getaddrinfo failed)"))

During handling of the above exception, another exception occurred:

Traceback (most recent call last):
  File "C:\My_programms\JetBrains\PyCharm Community Edition 2023.3.2\My_programms\tg_voise\.venv\Lib\site-packages\telebot\__init__.py", line 1081, in infinity_polling
    self.polling(non_stop=True, timeout=timeout, long_polling_timeout=long_polling_timeout,
  File "C:\My_programms\JetBrains\PyCharm Community Edition 2023.3.2\My_programms\tg_voise\.venv\Lib\site-packages\telebot\__init__.py", line 1169, in polling
    self.__threaded_polling(non_stop=non_stop, interval=interval, timeout=timeout, long_polling_timeout=long_polling_timeout,
  File "C:\My_programms\JetBrains\PyCharm Community Edition 2023.3.2\My_programms\tg_voise\.venv\Lib\site-packages\telebot\__init__.py", line 1244, in __threaded_polling
    raise e
  File "C:\My_programms\JetBrains\PyCharm Community Edition 2023.3.2\My_programms\tg_voise\.venv\Lib\site-packages\telebot\__init__.py", line 1205, in __threaded_polling
    polling_thread.raise_exceptions()
  File "C:\My_programms\JetBrains\PyCharm Community Edition 2023.3.2\My_programms\tg_voise\.venv\Lib\site-packages\telebot\util.py", line 111, in raise_exceptions
    raise self.exception_info
  File "C:\My_programms\JetBrains\PyCharm Community Edition 2023.3.2\My_programms\tg_voise\.venv\Lib\site-packages\telebot\util.py", line 93, in run
    task(*args, **kwargs)
  File "C:\My_programms\JetBrains\PyCharm Community Edition 2023.3.2\My_programms\tg_voise\.venv\Lib\site-packages\telebot\__init__.py", line 675, in __retrieve_updates
    updates = self.get_updates(offset=(self.last_update_id + 1),
             ^^^^^^^^^^^^^^^^^^^^^^^^^^^^^^^^^^^^^^^^^^^^^^^^^^
  File "C:\My_programms\JetBrains\PyCharm Community Edition 2023.3.2\My_programms\tg_voise\.venv\Lib\site-packages\telebot\__init__.py", line 647, in get_updates
    json_updates = apihelper.get_updates(
                   ^^^^^^^^^^^^^^^^^^^^^^
  File "C:\My_programms\JetBrains\PyCharm Community Edition 2023.3.2\My_programms\tg_voise\.venv\Lib\site-packages\telebot\apihelper.py", line 327, in get_updates
    return _make_request(token, method_url, params=payload)
           ^^^^^^^^^^^^^^^^^^^^^^^^^^^^^^^^^^^^^^^^^^^^^^^^
  File "C:\My_programms\JetBrains\PyCharm Community Edition 2023.3.2\My_programms\tg_voise\.venv\Lib\site-packages\telebot\apihelper.py", line 161, in _make_request
    result = _get_req_session().request(
             ^^^^^^^^^^^^^^^^^^^^^^^^^^^
  File "C:\My_programms\JetBrains\PyCharm Community Edition 2023.3.2\My_programms\tg_voise\.venv\Lib\site-packages\requests\sessions.py", line 589, in request
    resp = self.send(prep, **send_kwargs)
           ^^^^^^^^^^^^^^^^^^^^^^^^^^^^^^
  File "C:\My_programms\JetBrains\PyCharm Community Edition 2023.3.2\My_programms\tg_voise\.venv\Lib\site-packages\requests\sessions.py", line 703, in send
    r = adapter.send(request, **kwargs)
        ^^^^^^^^^^^^^^^^^^^^^^^^^^^^^^^
  File "C:\My_programms\JetBrains\PyCharm Community Edition 2023.3.2\My_programms\tg_voise\.venv\Lib\site-packages\requests\adapters.py", line 519, in send
    raise ConnectionError(e, request=request)
requests.exceptions.ConnectionError: HTTPSConnectionPool(host='api.telegram.org', port=443): Max retries exceeded with url: /bot6565406578:AAHJXXP9C3YuGGrZavTnkhlJTq4hQl1V3KE/getUpdates?offset=585466214&timeout=20 (Caused by NameResolutionError("<urllib3.connection.HTTPSConnection object at 0x0000018DBCE3C8C0>: Failed to resolve 'api.telegram.org' ([Errno 11001] getaddrinfo failed)"))

2024-04-12 23:37:28,929 - TeleBot - ERROR - Infinity polling exception: HTTPSConnectionPool(host='api.telegram.org', port=443): Max retries exceeded with url: /bot6565406578:AAHJXXP9C3YuGGrZavTnkhlJTq4hQl1V3KE/getUpdates?offset=585466214&timeout=20 (Caused by NameResolutionError("<urllib3.connection.HTTPSConnection object at 0x0000018DBCE5C9B0>: Failed to resolve 'api.telegram.org' ([Errno 11001] getaddrinfo failed)"))
2024-04-12 23:37:28,932 - TeleBot - ERROR - Exception traceback:
Traceback (most recent call last):
  File "C:\My_programms\JetBrains\PyCharm Community Edition 2023.3.2\My_programms\tg_voise\.venv\Lib\site-packages\urllib3\connection.py", line 198, in _new_conn
    sock = connection.create_connection(
           ^^^^^^^^^^^^^^^^^^^^^^^^^^^^^
  File "C:\My_programms\JetBrains\PyCharm Community Edition 2023.3.2\My_programms\tg_voise\.venv\Lib\site-packages\urllib3\util\connection.py", line 60, in create_connection
    for res in socket.getaddrinfo(host, port, family, socket.SOCK_STREAM):
               ^^^^^^^^^^^^^^^^^^^^^^^^^^^^^^^^^^^^^^^^^^^^^^^^^^^^^^^^^^
  File "C:\Users\Asus\AppData\Local\Programs\Python\Python312\Lib\socket.py", line 963, in getaddrinfo
    for res in _socket.getaddrinfo(host, port, family, type, proto, flags):
               ^^^^^^^^^^^^^^^^^^^^^^^^^^^^^^^^^^^^^^^^^^^^^^^^^^^^^^^^^^^
socket.gaierror: [Errno 11001] getaddrinfo failed

The above exception was the direct cause of the following exception:

Traceback (most recent call last):
  File "C:\My_programms\JetBrains\PyCharm Community Edition 2023.3.2\My_programms\tg_voise\.venv\Lib\site-packages\urllib3\connectionpool.py", line 793, in urlopen
    response = self._make_request(
               ^^^^^^^^^^^^^^^^^^^
  File "C:\My_programms\JetBrains\PyCharm Community Edition 2023.3.2\My_programms\tg_voise\.venv\Lib\site-packages\urllib3\connectionpool.py", line 491, in _make_request
    raise new_e
  File "C:\My_programms\JetBrains\PyCharm Community Edition 2023.3.2\My_programms\tg_voise\.venv\Lib\site-packages\urllib3\connectionpool.py", line 467, in _make_request
    self._validate_conn(conn)
  File "C:\My_programms\JetBrains\PyCharm Community Edition 2023.3.2\My_programms\tg_voise\.venv\Lib\site-packages\urllib3\connectionpool.py", line 1099, in _validate_conn
    conn.connect()
  File "C:\My_programms\JetBrains\PyCharm Community Edition 2023.3.2\My_programms\tg_voise\.venv\Lib\site-packages\urllib3\connection.py", line 616, in connect
    self.sock = sock = self._new_conn()
                       ^^^^^^^^^^^^^^^^
  File "C:\My_programms\JetBrains\PyCharm Community Edition 2023.3.2\My_programms\tg_voise\.venv\Lib\site-packages\urllib3\connection.py", line 205, in _new_conn
    raise NameResolutionError(self.host, self, e) from e
urllib3.exceptions.NameResolutionError: <urllib3.connection.HTTPSConnection object at 0x0000018DBCE5C9B0>: Failed to resolve 'api.telegram.org' ([Errno 11001] getaddrinfo failed)

The above exception was the direct cause of the following exception:

Traceback (most recent call last):
  File "C:\My_programms\JetBrains\PyCharm Community Edition 2023.3.2\My_programms\tg_voise\.venv\Lib\site-packages\requests\adapters.py", line 486, in send
    resp = conn.urlopen(
           ^^^^^^^^^^^^^
  File "C:\My_programms\JetBrains\PyCharm Community Edition 2023.3.2\My_programms\tg_voise\.venv\Lib\site-packages\urllib3\connectionpool.py", line 847, in urlopen
    retries = retries.increment(
              ^^^^^^^^^^^^^^^^^^
  File "C:\My_programms\JetBrains\PyCharm Community Edition 2023.3.2\My_programms\tg_voise\.venv\Lib\site-packages\urllib3\util\retry.py", line 515, in increment
    raise MaxRetryError(_pool, url, reason) from reason  # type: ignore[arg-type]
    ^^^^^^^^^^^^^^^^^^^^^^^^^^^^^^^^^^^^^^^^^^^^^^^^^^^
urllib3.exceptions.MaxRetryError: HTTPSConnectionPool(host='api.telegram.org', port=443): Max retries exceeded with url: /bot6565406578:AAHJXXP9C3YuGGrZavTnkhlJTq4hQl1V3KE/getUpdates?offset=585466214&timeout=20 (Caused by NameResolutionError("<urllib3.connection.HTTPSConnection object at 0x0000018DBCE5C9B0>: Failed to resolve 'api.telegram.org' ([Errno 11001] getaddrinfo failed)"))

During handling of the above exception, another exception occurred:

Traceback (most recent call last):
  File "C:\My_programms\JetBrains\PyCharm Community Edition 2023.3.2\My_programms\tg_voise\.venv\Lib\site-packages\telebot\__init__.py", line 1081, in infinity_polling
    self.polling(non_stop=True, timeout=timeout, long_polling_timeout=long_polling_timeout,
  File "C:\My_programms\JetBrains\PyCharm Community Edition 2023.3.2\My_programms\tg_voise\.venv\Lib\site-packages\telebot\__init__.py", line 1169, in polling
    self.__threaded_polling(non_stop=non_stop, interval=interval, timeout=timeout, long_polling_timeout=long_polling_timeout,
  File "C:\My_programms\JetBrains\PyCharm Community Edition 2023.3.2\My_programms\tg_voise\.venv\Lib\site-packages\telebot\__init__.py", line 1244, in __threaded_polling
    raise e
  File "C:\My_programms\JetBrains\PyCharm Community Edition 2023.3.2\My_programms\tg_voise\.venv\Lib\site-packages\telebot\__init__.py", line 1205, in __threaded_polling
    polling_thread.raise_exceptions()
  File "C:\My_programms\JetBrains\PyCharm Community Edition 2023.3.2\My_programms\tg_voise\.venv\Lib\site-packages\telebot\util.py", line 111, in raise_exceptions
    raise self.exception_info
  File "C:\My_programms\JetBrains\PyCharm Community Edition 2023.3.2\My_programms\tg_voise\.venv\Lib\site-packages\telebot\util.py", line 93, in run
    task(*args, **kwargs)
  File "C:\My_programms\JetBrains\PyCharm Community Edition 2023.3.2\My_programms\tg_voise\.venv\Lib\site-packages\telebot\__init__.py", line 675, in __retrieve_updates
    updates = self.get_updates(offset=(self.last_update_id + 1),
             ^^^^^^^^^^^^^^^^^^^^^^^^^^^^^^^^^^^^^^^^^^^^^^^^^^
  File "C:\My_programms\JetBrains\PyCharm Community Edition 2023.3.2\My_programms\tg_voise\.venv\Lib\site-packages\telebot\__init__.py", line 647, in get_updates
    json_updates = apihelper.get_updates(
                   ^^^^^^^^^^^^^^^^^^^^^^
  File "C:\My_programms\JetBrains\PyCharm Community Edition 2023.3.2\My_programms\tg_voise\.venv\Lib\site-packages\telebot\apihelper.py", line 327, in get_updates
    return _make_request(token, method_url, params=payload)
           ^^^^^^^^^^^^^^^^^^^^^^^^^^^^^^^^^^^^^^^^^^^^^^^^
  File "C:\My_programms\JetBrains\PyCharm Community Edition 2023.3.2\My_programms\tg_voise\.venv\Lib\site-packages\telebot\apihelper.py", line 161, in _make_request
    result = _get_req_session().request(
             ^^^^^^^^^^^^^^^^^^^^^^^^^^^
  File "C:\My_programms\JetBrains\PyCharm Community Edition 2023.3.2\My_programms\tg_voise\.venv\Lib\site-packages\requests\sessions.py", line 589, in request
    resp = self.send(prep, **send_kwargs)
           ^^^^^^^^^^^^^^^^^^^^^^^^^^^^^^
  File "C:\My_programms\JetBrains\PyCharm Community Edition 2023.3.2\My_programms\tg_voise\.venv\Lib\site-packages\requests\sessions.py", line 703, in send
    r = adapter.send(request, **kwargs)
        ^^^^^^^^^^^^^^^^^^^^^^^^^^^^^^^
  File "C:\My_programms\JetBrains\PyCharm Community Edition 2023.3.2\My_programms\tg_voise\.venv\Lib\site-packages\requests\adapters.py", line 519, in send
    raise ConnectionError(e, request=request)
requests.exceptions.ConnectionError: HTTPSConnectionPool(host='api.telegram.org', port=443): Max retries exceeded with url: /bot6565406578:AAHJXXP9C3YuGGrZavTnkhlJTq4hQl1V3KE/getUpdates?offset=585466214&timeout=20 (Caused by NameResolutionError("<urllib3.connection.HTTPSConnection object at 0x0000018DBCE5C9B0>: Failed to resolve 'api.telegram.org' ([Errno 11001] getaddrinfo failed)"))

2024-04-12 23:37:31,954 - TeleBot - ERROR - Infinity polling exception: HTTPSConnectionPool(host='api.telegram.org', port=443): Max retries exceeded with url: /bot6565406578:AAHJXXP9C3YuGGrZavTnkhlJTq4hQl1V3KE/getUpdates?offset=585466214&timeout=20 (Caused by NameResolutionError("<urllib3.connection.HTTPSConnection object at 0x0000018DBCE3F980>: Failed to resolve 'api.telegram.org' ([Errno 11001] getaddrinfo failed)"))
2024-04-12 23:37:31,957 - TeleBot - ERROR - Exception traceback:
Traceback (most recent call last):
  File "C:\My_programms\JetBrains\PyCharm Community Edition 2023.3.2\My_programms\tg_voise\.venv\Lib\site-packages\urllib3\connection.py", line 198, in _new_conn
    sock = connection.create_connection(
           ^^^^^^^^^^^^^^^^^^^^^^^^^^^^^
  File "C:\My_programms\JetBrains\PyCharm Community Edition 2023.3.2\My_programms\tg_voise\.venv\Lib\site-packages\urllib3\util\connection.py", line 60, in create_connection
    for res in socket.getaddrinfo(host, port, family, socket.SOCK_STREAM):
               ^^^^^^^^^^^^^^^^^^^^^^^^^^^^^^^^^^^^^^^^^^^^^^^^^^^^^^^^^^
  File "C:\Users\Asus\AppData\Local\Programs\Python\Python312\Lib\socket.py", line 963, in getaddrinfo
    for res in _socket.getaddrinfo(host, port, family, type, proto, flags):
               ^^^^^^^^^^^^^^^^^^^^^^^^^^^^^^^^^^^^^^^^^^^^^^^^^^^^^^^^^^^
socket.gaierror: [Errno 11001] getaddrinfo failed

The above exception was the direct cause of the following exception:

Traceback (most recent call last):
  File "C:\My_programms\JetBrains\PyCharm Community Edition 2023.3.2\My_programms\tg_voise\.venv\Lib\site-packages\urllib3\connectionpool.py", line 793, in urlopen
    response = self._make_request(
               ^^^^^^^^^^^^^^^^^^^
  File "C:\My_programms\JetBrains\PyCharm Community Edition 2023.3.2\My_programms\tg_voise\.venv\Lib\site-packages\urllib3\connectionpool.py", line 491, in _make_request
    raise new_e
  File "C:\My_programms\JetBrains\PyCharm Community Edition 2023.3.2\My_programms\tg_voise\.venv\Lib\site-packages\urllib3\connectionpool.py", line 467, in _make_request
    self._validate_conn(conn)
  File "C:\My_programms\JetBrains\PyCharm Community Edition 2023.3.2\My_programms\tg_voise\.venv\Lib\site-packages\urllib3\connectionpool.py", line 1099, in _validate_conn
    conn.connect()
  File "C:\My_programms\JetBrains\PyCharm Community Edition 2023.3.2\My_programms\tg_voise\.venv\Lib\site-packages\urllib3\connection.py", line 616, in connect
    self.sock = sock = self._new_conn()
                       ^^^^^^^^^^^^^^^^
  File "C:\My_programms\JetBrains\PyCharm Community Edition 2023.3.2\My_programms\tg_voise\.venv\Lib\site-packages\urllib3\connection.py", line 205, in _new_conn
    raise NameResolutionError(self.host, self, e) from e
urllib3.exceptions.NameResolutionError: <urllib3.connection.HTTPSConnection object at 0x0000018DBCE3F980>: Failed to resolve 'api.telegram.org' ([Errno 11001] getaddrinfo failed)

The above exception was the direct cause of the following exception:

Traceback (most recent call last):
  File "C:\My_programms\JetBrains\PyCharm Community Edition 2023.3.2\My_programms\tg_voise\.venv\Lib\site-packages\requests\adapters.py", line 486, in send
    resp = conn.urlopen(
           ^^^^^^^^^^^^^
  File "C:\My_programms\JetBrains\PyCharm Community Edition 2023.3.2\My_programms\tg_voise\.venv\Lib\site-packages\urllib3\connectionpool.py", line 847, in urlopen
    retries = retries.increment(
              ^^^^^^^^^^^^^^^^^^
  File "C:\My_programms\JetBrains\PyCharm Community Edition 2023.3.2\My_programms\tg_voise\.venv\Lib\site-packages\urllib3\util\retry.py", line 515, in increment
    raise MaxRetryError(_pool, url, reason) from reason  # type: ignore[arg-type]
    ^^^^^^^^^^^^^^^^^^^^^^^^^^^^^^^^^^^^^^^^^^^^^^^^^^^
urllib3.exceptions.MaxRetryError: HTTPSConnectionPool(host='api.telegram.org', port=443): Max retries exceeded with url: /bot6565406578:AAHJXXP9C3YuGGrZavTnkhlJTq4hQl1V3KE/getUpdates?offset=585466214&timeout=20 (Caused by NameResolutionError("<urllib3.connection.HTTPSConnection object at 0x0000018DBCE3F980>: Failed to resolve 'api.telegram.org' ([Errno 11001] getaddrinfo failed)"))

During handling of the above exception, another exception occurred:

Traceback (most recent call last):
  File "C:\My_programms\JetBrains\PyCharm Community Edition 2023.3.2\My_programms\tg_voise\.venv\Lib\site-packages\telebot\__init__.py", line 1081, in infinity_polling
    self.polling(non_stop=True, timeout=timeout, long_polling_timeout=long_polling_timeout,
  File "C:\My_programms\JetBrains\PyCharm Community Edition 2023.3.2\My_programms\tg_voise\.venv\Lib\site-packages\telebot\__init__.py", line 1169, in polling
    self.__threaded_polling(non_stop=non_stop, interval=interval, timeout=timeout, long_polling_timeout=long_polling_timeout,
  File "C:\My_programms\JetBrains\PyCharm Community Edition 2023.3.2\My_programms\tg_voise\.venv\Lib\site-packages\telebot\__init__.py", line 1244, in __threaded_polling
    raise e
  File "C:\My_programms\JetBrains\PyCharm Community Edition 2023.3.2\My_programms\tg_voise\.venv\Lib\site-packages\telebot\__init__.py", line 1205, in __threaded_polling
    polling_thread.raise_exceptions()
  File "C:\My_programms\JetBrains\PyCharm Community Edition 2023.3.2\My_programms\tg_voise\.venv\Lib\site-packages\telebot\util.py", line 111, in raise_exceptions
    raise self.exception_info
  File "C:\My_programms\JetBrains\PyCharm Community Edition 2023.3.2\My_programms\tg_voise\.venv\Lib\site-packages\telebot\util.py", line 93, in run
    task(*args, **kwargs)
  File "C:\My_programms\JetBrains\PyCharm Community Edition 2023.3.2\My_programms\tg_voise\.venv\Lib\site-packages\telebot\__init__.py", line 675, in __retrieve_updates
    updates = self.get_updates(offset=(self.last_update_id + 1),
             ^^^^^^^^^^^^^^^^^^^^^^^^^^^^^^^^^^^^^^^^^^^^^^^^^^
  File "C:\My_programms\JetBrains\PyCharm Community Edition 2023.3.2\My_programms\tg_voise\.venv\Lib\site-packages\telebot\__init__.py", line 647, in get_updates
    json_updates = apihelper.get_updates(
                   ^^^^^^^^^^^^^^^^^^^^^^
  File "C:\My_programms\JetBrains\PyCharm Community Edition 2023.3.2\My_programms\tg_voise\.venv\Lib\site-packages\telebot\apihelper.py", line 327, in get_updates
    return _make_request(token, method_url, params=payload)
           ^^^^^^^^^^^^^^^^^^^^^^^^^^^^^^^^^^^^^^^^^^^^^^^^
  File "C:\My_programms\JetBrains\PyCharm Community Edition 2023.3.2\My_programms\tg_voise\.venv\Lib\site-packages\telebot\apihelper.py", line 161, in _make_request
    result = _get_req_session().request(
             ^^^^^^^^^^^^^^^^^^^^^^^^^^^
  File "C:\My_programms\JetBrains\PyCharm Community Edition 2023.3.2\My_programms\tg_voise\.venv\Lib\site-packages\requests\sessions.py", line 589, in request
    resp = self.send(prep, **send_kwargs)
           ^^^^^^^^^^^^^^^^^^^^^^^^^^^^^^
  File "C:\My_programms\JetBrains\PyCharm Community Edition 2023.3.2\My_programms\tg_voise\.venv\Lib\site-packages\requests\sessions.py", line 703, in send
    r = adapter.send(request, **kwargs)
        ^^^^^^^^^^^^^^^^^^^^^^^^^^^^^^^
  File "C:\My_programms\JetBrains\PyCharm Community Edition 2023.3.2\My_programms\tg_voise\.venv\Lib\site-packages\requests\adapters.py", line 519, in send
    raise ConnectionError(e, request=request)
requests.exceptions.ConnectionError: HTTPSConnectionPool(host='api.telegram.org', port=443): Max retries exceeded with url: /bot6565406578:AAHJXXP9C3YuGGrZavTnkhlJTq4hQl1V3KE/getUpdates?offset=585466214&timeout=20 (Caused by NameResolutionError("<urllib3.connection.HTTPSConnection object at 0x0000018DBCE3F980>: Failed to resolve 'api.telegram.org' ([Errno 11001] getaddrinfo failed)"))

2024-04-12 23:37:34,966 - TeleBot - ERROR - Infinity polling exception: HTTPSConnectionPool(host='api.telegram.org', port=443): Max retries exceeded with url: /bot6565406578:AAHJXXP9C3YuGGrZavTnkhlJTq4hQl1V3KE/getUpdates?offset=585466214&timeout=20 (Caused by NameResolutionError("<urllib3.connection.HTTPSConnection object at 0x0000018DBC43F350>: Failed to resolve 'api.telegram.org' ([Errno 11001] getaddrinfo failed)"))
2024-04-12 23:37:34,969 - TeleBot - ERROR - Exception traceback:
Traceback (most recent call last):
  File "C:\My_programms\JetBrains\PyCharm Community Edition 2023.3.2\My_programms\tg_voise\.venv\Lib\site-packages\urllib3\connection.py", line 198, in _new_conn
    sock = connection.create_connection(
           ^^^^^^^^^^^^^^^^^^^^^^^^^^^^^
  File "C:\My_programms\JetBrains\PyCharm Community Edition 2023.3.2\My_programms\tg_voise\.venv\Lib\site-packages\urllib3\util\connection.py", line 60, in create_connection
    for res in socket.getaddrinfo(host, port, family, socket.SOCK_STREAM):
               ^^^^^^^^^^^^^^^^^^^^^^^^^^^^^^^^^^^^^^^^^^^^^^^^^^^^^^^^^^
  File "C:\Users\Asus\AppData\Local\Programs\Python\Python312\Lib\socket.py", line 963, in getaddrinfo
    for res in _socket.getaddrinfo(host, port, family, type, proto, flags):
               ^^^^^^^^^^^^^^^^^^^^^^^^^^^^^^^^^^^^^^^^^^^^^^^^^^^^^^^^^^^
socket.gaierror: [Errno 11001] getaddrinfo failed

The above exception was the direct cause of the following exception:

Traceback (most recent call last):
  File "C:\My_programms\JetBrains\PyCharm Community Edition 2023.3.2\My_programms\tg_voise\.venv\Lib\site-packages\urllib3\connectionpool.py", line 793, in urlopen
    response = self._make_request(
               ^^^^^^^^^^^^^^^^^^^
  File "C:\My_programms\JetBrains\PyCharm Community Edition 2023.3.2\My_programms\tg_voise\.venv\Lib\site-packages\urllib3\connectionpool.py", line 491, in _make_request
    raise new_e
  File "C:\My_programms\JetBrains\PyCharm Community Edition 2023.3.2\My_programms\tg_voise\.venv\Lib\site-packages\urllib3\connectionpool.py", line 467, in _make_request
    self._validate_conn(conn)
  File "C:\My_programms\JetBrains\PyCharm Community Edition 2023.3.2\My_programms\tg_voise\.venv\Lib\site-packages\urllib3\connectionpool.py", line 1099, in _validate_conn
    conn.connect()
  File "C:\My_programms\JetBrains\PyCharm Community Edition 2023.3.2\My_programms\tg_voise\.venv\Lib\site-packages\urllib3\connection.py", line 616, in connect
    self.sock = sock = self._new_conn()
                       ^^^^^^^^^^^^^^^^
  File "C:\My_programms\JetBrains\PyCharm Community Edition 2023.3.2\My_programms\tg_voise\.venv\Lib\site-packages\urllib3\connection.py", line 205, in _new_conn
    raise NameResolutionError(self.host, self, e) from e
urllib3.exceptions.NameResolutionError: <urllib3.connection.HTTPSConnection object at 0x0000018DBC43F350>: Failed to resolve 'api.telegram.org' ([Errno 11001] getaddrinfo failed)

The above exception was the direct cause of the following exception:

Traceback (most recent call last):
  File "C:\My_programms\JetBrains\PyCharm Community Edition 2023.3.2\My_programms\tg_voise\.venv\Lib\site-packages\requests\adapters.py", line 486, in send
    resp = conn.urlopen(
           ^^^^^^^^^^^^^
  File "C:\My_programms\JetBrains\PyCharm Community Edition 2023.3.2\My_programms\tg_voise\.venv\Lib\site-packages\urllib3\connectionpool.py", line 847, in urlopen
    retries = retries.increment(
              ^^^^^^^^^^^^^^^^^^
  File "C:\My_programms\JetBrains\PyCharm Community Edition 2023.3.2\My_programms\tg_voise\.venv\Lib\site-packages\urllib3\util\retry.py", line 515, in increment
    raise MaxRetryError(_pool, url, reason) from reason  # type: ignore[arg-type]
    ^^^^^^^^^^^^^^^^^^^^^^^^^^^^^^^^^^^^^^^^^^^^^^^^^^^
urllib3.exceptions.MaxRetryError: HTTPSConnectionPool(host='api.telegram.org', port=443): Max retries exceeded with url: /bot6565406578:AAHJXXP9C3YuGGrZavTnkhlJTq4hQl1V3KE/getUpdates?offset=585466214&timeout=20 (Caused by NameResolutionError("<urllib3.connection.HTTPSConnection object at 0x0000018DBC43F350>: Failed to resolve 'api.telegram.org' ([Errno 11001] getaddrinfo failed)"))

During handling of the above exception, another exception occurred:

Traceback (most recent call last):
  File "C:\My_programms\JetBrains\PyCharm Community Edition 2023.3.2\My_programms\tg_voise\.venv\Lib\site-packages\telebot\__init__.py", line 1081, in infinity_polling
    self.polling(non_stop=True, timeout=timeout, long_polling_timeout=long_polling_timeout,
  File "C:\My_programms\JetBrains\PyCharm Community Edition 2023.3.2\My_programms\tg_voise\.venv\Lib\site-packages\telebot\__init__.py", line 1169, in polling
    self.__threaded_polling(non_stop=non_stop, interval=interval, timeout=timeout, long_polling_timeout=long_polling_timeout,
  File "C:\My_programms\JetBrains\PyCharm Community Edition 2023.3.2\My_programms\tg_voise\.venv\Lib\site-packages\telebot\__init__.py", line 1244, in __threaded_polling
    raise e
  File "C:\My_programms\JetBrains\PyCharm Community Edition 2023.3.2\My_programms\tg_voise\.venv\Lib\site-packages\telebot\__init__.py", line 1205, in __threaded_polling
    polling_thread.raise_exceptions()
  File "C:\My_programms\JetBrains\PyCharm Community Edition 2023.3.2\My_programms\tg_voise\.venv\Lib\site-packages\telebot\util.py", line 111, in raise_exceptions
    raise self.exception_info
  File "C:\My_programms\JetBrains\PyCharm Community Edition 2023.3.2\My_programms\tg_voise\.venv\Lib\site-packages\telebot\util.py", line 93, in run
    task(*args, **kwargs)
  File "C:\My_programms\JetBrains\PyCharm Community Edition 2023.3.2\My_programms\tg_voise\.venv\Lib\site-packages\telebot\__init__.py", line 675, in __retrieve_updates
    updates = self.get_updates(offset=(self.last_update_id + 1),
             ^^^^^^^^^^^^^^^^^^^^^^^^^^^^^^^^^^^^^^^^^^^^^^^^^^
  File "C:\My_programms\JetBrains\PyCharm Community Edition 2023.3.2\My_programms\tg_voise\.venv\Lib\site-packages\telebot\__init__.py", line 647, in get_updates
    json_updates = apihelper.get_updates(
                   ^^^^^^^^^^^^^^^^^^^^^^
  File "C:\My_programms\JetBrains\PyCharm Community Edition 2023.3.2\My_programms\tg_voise\.venv\Lib\site-packages\telebot\apihelper.py", line 327, in get_updates
    return _make_request(token, method_url, params=payload)
           ^^^^^^^^^^^^^^^^^^^^^^^^^^^^^^^^^^^^^^^^^^^^^^^^
  File "C:\My_programms\JetBrains\PyCharm Community Edition 2023.3.2\My_programms\tg_voise\.venv\Lib\site-packages\telebot\apihelper.py", line 161, in _make_request
    result = _get_req_session().request(
             ^^^^^^^^^^^^^^^^^^^^^^^^^^^
  File "C:\My_programms\JetBrains\PyCharm Community Edition 2023.3.2\My_programms\tg_voise\.venv\Lib\site-packages\requests\sessions.py", line 589, in request
    resp = self.send(prep, **send_kwargs)
           ^^^^^^^^^^^^^^^^^^^^^^^^^^^^^^
  File "C:\My_programms\JetBrains\PyCharm Community Edition 2023.3.2\My_programms\tg_voise\.venv\Lib\site-packages\requests\sessions.py", line 703, in send
    r = adapter.send(request, **kwargs)
        ^^^^^^^^^^^^^^^^^^^^^^^^^^^^^^^
  File "C:\My_programms\JetBrains\PyCharm Community Edition 2023.3.2\My_programms\tg_voise\.venv\Lib\site-packages\requests\adapters.py", line 519, in send
    raise ConnectionError(e, request=request)
requests.exceptions.ConnectionError: HTTPSConnectionPool(host='api.telegram.org', port=443): Max retries exceeded with url: /bot6565406578:AAHJXXP9C3YuGGrZavTnkhlJTq4hQl1V3KE/getUpdates?offset=585466214&timeout=20 (Caused by NameResolutionError("<urllib3.connection.HTTPSConnection object at 0x0000018DBC43F350>: Failed to resolve 'api.telegram.org' ([Errno 11001] getaddrinfo failed)"))

2024-04-12 23:37:37,977 - TeleBot - ERROR - Infinity polling exception: HTTPSConnectionPool(host='api.telegram.org', port=443): Max retries exceeded with url: /bot6565406578:AAHJXXP9C3YuGGrZavTnkhlJTq4hQl1V3KE/getUpdates?offset=585466214&timeout=20 (Caused by NameResolutionError("<urllib3.connection.HTTPSConnection object at 0x0000018DBCE5DAC0>: Failed to resolve 'api.telegram.org' ([Errno 11001] getaddrinfo failed)"))
2024-04-12 23:37:37,980 - TeleBot - ERROR - Exception traceback:
Traceback (most recent call last):
  File "C:\My_programms\JetBrains\PyCharm Community Edition 2023.3.2\My_programms\tg_voise\.venv\Lib\site-packages\urllib3\connection.py", line 198, in _new_conn
    sock = connection.create_connection(
           ^^^^^^^^^^^^^^^^^^^^^^^^^^^^^
  File "C:\My_programms\JetBrains\PyCharm Community Edition 2023.3.2\My_programms\tg_voise\.venv\Lib\site-packages\urllib3\util\connection.py", line 60, in create_connection
    for res in socket.getaddrinfo(host, port, family, socket.SOCK_STREAM):
               ^^^^^^^^^^^^^^^^^^^^^^^^^^^^^^^^^^^^^^^^^^^^^^^^^^^^^^^^^^
  File "C:\Users\Asus\AppData\Local\Programs\Python\Python312\Lib\socket.py", line 963, in getaddrinfo
    for res in _socket.getaddrinfo(host, port, family, type, proto, flags):
               ^^^^^^^^^^^^^^^^^^^^^^^^^^^^^^^^^^^^^^^^^^^^^^^^^^^^^^^^^^^
socket.gaierror: [Errno 11001] getaddrinfo failed

The above exception was the direct cause of the following exception:

Traceback (most recent call last):
  File "C:\My_programms\JetBrains\PyCharm Community Edition 2023.3.2\My_programms\tg_voise\.venv\Lib\site-packages\urllib3\connectionpool.py", line 793, in urlopen
    response = self._make_request(
               ^^^^^^^^^^^^^^^^^^^
  File "C:\My_programms\JetBrains\PyCharm Community Edition 2023.3.2\My_programms\tg_voise\.venv\Lib\site-packages\urllib3\connectionpool.py", line 491, in _make_request
    raise new_e
  File "C:\My_programms\JetBrains\PyCharm Community Edition 2023.3.2\My_programms\tg_voise\.venv\Lib\site-packages\urllib3\connectionpool.py", line 467, in _make_request
    self._validate_conn(conn)
  File "C:\My_programms\JetBrains\PyCharm Community Edition 2023.3.2\My_programms\tg_voise\.venv\Lib\site-packages\urllib3\connectionpool.py", line 1099, in _validate_conn
    conn.connect()
  File "C:\My_programms\JetBrains\PyCharm Community Edition 2023.3.2\My_programms\tg_voise\.venv\Lib\site-packages\urllib3\connection.py", line 616, in connect
    self.sock = sock = self._new_conn()
                       ^^^^^^^^^^^^^^^^
  File "C:\My_programms\JetBrains\PyCharm Community Edition 2023.3.2\My_programms\tg_voise\.venv\Lib\site-packages\urllib3\connection.py", line 205, in _new_conn
    raise NameResolutionError(self.host, self, e) from e
urllib3.exceptions.NameResolutionError: <urllib3.connection.HTTPSConnection object at 0x0000018DBCE5DAC0>: Failed to resolve 'api.telegram.org' ([Errno 11001] getaddrinfo failed)

The above exception was the direct cause of the following exception:

Traceback (most recent call last):
  File "C:\My_programms\JetBrains\PyCharm Community Edition 2023.3.2\My_programms\tg_voise\.venv\Lib\site-packages\requests\adapters.py", line 486, in send
    resp = conn.urlopen(
           ^^^^^^^^^^^^^
  File "C:\My_programms\JetBrains\PyCharm Community Edition 2023.3.2\My_programms\tg_voise\.venv\Lib\site-packages\urllib3\connectionpool.py", line 847, in urlopen
    retries = retries.increment(
              ^^^^^^^^^^^^^^^^^^
  File "C:\My_programms\JetBrains\PyCharm Community Edition 2023.3.2\My_programms\tg_voise\.venv\Lib\site-packages\urllib3\util\retry.py", line 515, in increment
    raise MaxRetryError(_pool, url, reason) from reason  # type: ignore[arg-type]
    ^^^^^^^^^^^^^^^^^^^^^^^^^^^^^^^^^^^^^^^^^^^^^^^^^^^
urllib3.exceptions.MaxRetryError: HTTPSConnectionPool(host='api.telegram.org', port=443): Max retries exceeded with url: /bot6565406578:AAHJXXP9C3YuGGrZavTnkhlJTq4hQl1V3KE/getUpdates?offset=585466214&timeout=20 (Caused by NameResolutionError("<urllib3.connection.HTTPSConnection object at 0x0000018DBCE5DAC0>: Failed to resolve 'api.telegram.org' ([Errno 11001] getaddrinfo failed)"))

During handling of the above exception, another exception occurred:

Traceback (most recent call last):
  File "C:\My_programms\JetBrains\PyCharm Community Edition 2023.3.2\My_programms\tg_voise\.venv\Lib\site-packages\telebot\__init__.py", line 1081, in infinity_polling
    self.polling(non_stop=True, timeout=timeout, long_polling_timeout=long_polling_timeout,
  File "C:\My_programms\JetBrains\PyCharm Community Edition 2023.3.2\My_programms\tg_voise\.venv\Lib\site-packages\telebot\__init__.py", line 1169, in polling
    self.__threaded_polling(non_stop=non_stop, interval=interval, timeout=timeout, long_polling_timeout=long_polling_timeout,
  File "C:\My_programms\JetBrains\PyCharm Community Edition 2023.3.2\My_programms\tg_voise\.venv\Lib\site-packages\telebot\__init__.py", line 1244, in __threaded_polling
    raise e
  File "C:\My_programms\JetBrains\PyCharm Community Edition 2023.3.2\My_programms\tg_voise\.venv\Lib\site-packages\telebot\__init__.py", line 1205, in __threaded_polling
    polling_thread.raise_exceptions()
  File "C:\My_programms\JetBrains\PyCharm Community Edition 2023.3.2\My_programms\tg_voise\.venv\Lib\site-packages\telebot\util.py", line 111, in raise_exceptions
    raise self.exception_info
  File "C:\My_programms\JetBrains\PyCharm Community Edition 2023.3.2\My_programms\tg_voise\.venv\Lib\site-packages\telebot\util.py", line 93, in run
    task(*args, **kwargs)
  File "C:\My_programms\JetBrains\PyCharm Community Edition 2023.3.2\My_programms\tg_voise\.venv\Lib\site-packages\telebot\__init__.py", line 675, in __retrieve_updates
    updates = self.get_updates(offset=(self.last_update_id + 1),
             ^^^^^^^^^^^^^^^^^^^^^^^^^^^^^^^^^^^^^^^^^^^^^^^^^^
  File "C:\My_programms\JetBrains\PyCharm Community Edition 2023.3.2\My_programms\tg_voise\.venv\Lib\site-packages\telebot\__init__.py", line 647, in get_updates
    json_updates = apihelper.get_updates(
                   ^^^^^^^^^^^^^^^^^^^^^^
  File "C:\My_programms\JetBrains\PyCharm Community Edition 2023.3.2\My_programms\tg_voise\.venv\Lib\site-packages\telebot\apihelper.py", line 327, in get_updates
    return _make_request(token, method_url, params=payload)
           ^^^^^^^^^^^^^^^^^^^^^^^^^^^^^^^^^^^^^^^^^^^^^^^^
  File "C:\My_programms\JetBrains\PyCharm Community Edition 2023.3.2\My_programms\tg_voise\.venv\Lib\site-packages\telebot\apihelper.py", line 161, in _make_request
    result = _get_req_session().request(
             ^^^^^^^^^^^^^^^^^^^^^^^^^^^
  File "C:\My_programms\JetBrains\PyCharm Community Edition 2023.3.2\My_programms\tg_voise\.venv\Lib\site-packages\requests\sessions.py", line 589, in request
    resp = self.send(prep, **send_kwargs)
           ^^^^^^^^^^^^^^^^^^^^^^^^^^^^^^
  File "C:\My_programms\JetBrains\PyCharm Community Edition 2023.3.2\My_programms\tg_voise\.venv\Lib\site-packages\requests\sessions.py", line 703, in send
    r = adapter.send(request, **kwargs)
        ^^^^^^^^^^^^^^^^^^^^^^^^^^^^^^^
  File "C:\My_programms\JetBrains\PyCharm Community Edition 2023.3.2\My_programms\tg_voise\.venv\Lib\site-packages\requests\adapters.py", line 519, in send
    raise ConnectionError(e, request=request)
requests.exceptions.ConnectionError: HTTPSConnectionPool(host='api.telegram.org', port=443): Max retries exceeded with url: /bot6565406578:AAHJXXP9C3YuGGrZavTnkhlJTq4hQl1V3KE/getUpdates?offset=585466214&timeout=20 (Caused by NameResolutionError("<urllib3.connection.HTTPSConnection object at 0x0000018DBCE5DAC0>: Failed to resolve 'api.telegram.org' ([Errno 11001] getaddrinfo failed)"))

2024-04-12 23:37:40,997 - TeleBot - ERROR - Infinity polling exception: HTTPSConnectionPool(host='api.telegram.org', port=443): Max retries exceeded with url: /bot6565406578:AAHJXXP9C3YuGGrZavTnkhlJTq4hQl1V3KE/getUpdates?offset=585466214&timeout=20 (Caused by NameResolutionError("<urllib3.connection.HTTPSConnection object at 0x0000018DBC3A9220>: Failed to resolve 'api.telegram.org' ([Errno 11001] getaddrinfo failed)"))
2024-04-12 23:37:41,001 - TeleBot - ERROR - Exception traceback:
Traceback (most recent call last):
  File "C:\My_programms\JetBrains\PyCharm Community Edition 2023.3.2\My_programms\tg_voise\.venv\Lib\site-packages\urllib3\connection.py", line 198, in _new_conn
    sock = connection.create_connection(
           ^^^^^^^^^^^^^^^^^^^^^^^^^^^^^
  File "C:\My_programms\JetBrains\PyCharm Community Edition 2023.3.2\My_programms\tg_voise\.venv\Lib\site-packages\urllib3\util\connection.py", line 60, in create_connection
    for res in socket.getaddrinfo(host, port, family, socket.SOCK_STREAM):
               ^^^^^^^^^^^^^^^^^^^^^^^^^^^^^^^^^^^^^^^^^^^^^^^^^^^^^^^^^^
  File "C:\Users\Asus\AppData\Local\Programs\Python\Python312\Lib\socket.py", line 963, in getaddrinfo
    for res in _socket.getaddrinfo(host, port, family, type, proto, flags):
               ^^^^^^^^^^^^^^^^^^^^^^^^^^^^^^^^^^^^^^^^^^^^^^^^^^^^^^^^^^^
socket.gaierror: [Errno 11001] getaddrinfo failed

The above exception was the direct cause of the following exception:

Traceback (most recent call last):
  File "C:\My_programms\JetBrains\PyCharm Community Edition 2023.3.2\My_programms\tg_voise\.venv\Lib\site-packages\urllib3\connectionpool.py", line 793, in urlopen
    response = self._make_request(
               ^^^^^^^^^^^^^^^^^^^
  File "C:\My_programms\JetBrains\PyCharm Community Edition 2023.3.2\My_programms\tg_voise\.venv\Lib\site-packages\urllib3\connectionpool.py", line 491, in _make_request
    raise new_e
  File "C:\My_programms\JetBrains\PyCharm Community Edition 2023.3.2\My_programms\tg_voise\.venv\Lib\site-packages\urllib3\connectionpool.py", line 467, in _make_request
    self._validate_conn(conn)
  File "C:\My_programms\JetBrains\PyCharm Community Edition 2023.3.2\My_programms\tg_voise\.venv\Lib\site-packages\urllib3\connectionpool.py", line 1099, in _validate_conn
    conn.connect()
  File "C:\My_programms\JetBrains\PyCharm Community Edition 2023.3.2\My_programms\tg_voise\.venv\Lib\site-packages\urllib3\connection.py", line 616, in connect
    self.sock = sock = self._new_conn()
                       ^^^^^^^^^^^^^^^^
  File "C:\My_programms\JetBrains\PyCharm Community Edition 2023.3.2\My_programms\tg_voise\.venv\Lib\site-packages\urllib3\connection.py", line 205, in _new_conn
    raise NameResolutionError(self.host, self, e) from e
urllib3.exceptions.NameResolutionError: <urllib3.connection.HTTPSConnection object at 0x0000018DBC3A9220>: Failed to resolve 'api.telegram.org' ([Errno 11001] getaddrinfo failed)

The above exception was the direct cause of the following exception:

Traceback (most recent call last):
  File "C:\My_programms\JetBrains\PyCharm Community Edition 2023.3.2\My_programms\tg_voise\.venv\Lib\site-packages\requests\adapters.py", line 486, in send
    resp = conn.urlopen(
           ^^^^^^^^^^^^^
  File "C:\My_programms\JetBrains\PyCharm Community Edition 2023.3.2\My_programms\tg_voise\.venv\Lib\site-packages\urllib3\connectionpool.py", line 847, in urlopen
    retries = retries.increment(
              ^^^^^^^^^^^^^^^^^^
  File "C:\My_programms\JetBrains\PyCharm Community Edition 2023.3.2\My_programms\tg_voise\.venv\Lib\site-packages\urllib3\util\retry.py", line 515, in increment
    raise MaxRetryError(_pool, url, reason) from reason  # type: ignore[arg-type]
    ^^^^^^^^^^^^^^^^^^^^^^^^^^^^^^^^^^^^^^^^^^^^^^^^^^^
urllib3.exceptions.MaxRetryError: HTTPSConnectionPool(host='api.telegram.org', port=443): Max retries exceeded with url: /bot6565406578:AAHJXXP9C3YuGGrZavTnkhlJTq4hQl1V3KE/getUpdates?offset=585466214&timeout=20 (Caused by NameResolutionError("<urllib3.connection.HTTPSConnection object at 0x0000018DBC3A9220>: Failed to resolve 'api.telegram.org' ([Errno 11001] getaddrinfo failed)"))

During handling of the above exception, another exception occurred:

Traceback (most recent call last):
  File "C:\My_programms\JetBrains\PyCharm Community Edition 2023.3.2\My_programms\tg_voise\.venv\Lib\site-packages\telebot\__init__.py", line 1081, in infinity_polling
    self.polling(non_stop=True, timeout=timeout, long_polling_timeout=long_polling_timeout,
  File "C:\My_programms\JetBrains\PyCharm Community Edition 2023.3.2\My_programms\tg_voise\.venv\Lib\site-packages\telebot\__init__.py", line 1169, in polling
    self.__threaded_polling(non_stop=non_stop, interval=interval, timeout=timeout, long_polling_timeout=long_polling_timeout,
  File "C:\My_programms\JetBrains\PyCharm Community Edition 2023.3.2\My_programms\tg_voise\.venv\Lib\site-packages\telebot\__init__.py", line 1244, in __threaded_polling
    raise e
  File "C:\My_programms\JetBrains\PyCharm Community Edition 2023.3.2\My_programms\tg_voise\.venv\Lib\site-packages\telebot\__init__.py", line 1205, in __threaded_polling
    polling_thread.raise_exceptions()
  File "C:\My_programms\JetBrains\PyCharm Community Edition 2023.3.2\My_programms\tg_voise\.venv\Lib\site-packages\telebot\util.py", line 111, in raise_exceptions
    raise self.exception_info
  File "C:\My_programms\JetBrains\PyCharm Community Edition 2023.3.2\My_programms\tg_voise\.venv\Lib\site-packages\telebot\util.py", line 93, in run
    task(*args, **kwargs)
  File "C:\My_programms\JetBrains\PyCharm Community Edition 2023.3.2\My_programms\tg_voise\.venv\Lib\site-packages\telebot\__init__.py", line 675, in __retrieve_updates
    updates = self.get_updates(offset=(self.last_update_id + 1),
             ^^^^^^^^^^^^^^^^^^^^^^^^^^^^^^^^^^^^^^^^^^^^^^^^^^
  File "C:\My_programms\JetBrains\PyCharm Community Edition 2023.3.2\My_programms\tg_voise\.venv\Lib\site-packages\telebot\__init__.py", line 647, in get_updates
    json_updates = apihelper.get_updates(
                   ^^^^^^^^^^^^^^^^^^^^^^
  File "C:\My_programms\JetBrains\PyCharm Community Edition 2023.3.2\My_programms\tg_voise\.venv\Lib\site-packages\telebot\apihelper.py", line 327, in get_updates
    return _make_request(token, method_url, params=payload)
           ^^^^^^^^^^^^^^^^^^^^^^^^^^^^^^^^^^^^^^^^^^^^^^^^
  File "C:\My_programms\JetBrains\PyCharm Community Edition 2023.3.2\My_programms\tg_voise\.venv\Lib\site-packages\telebot\apihelper.py", line 161, in _make_request
    result = _get_req_session().request(
             ^^^^^^^^^^^^^^^^^^^^^^^^^^^
  File "C:\My_programms\JetBrains\PyCharm Community Edition 2023.3.2\My_programms\tg_voise\.venv\Lib\site-packages\requests\sessions.py", line 589, in request
    resp = self.send(prep, **send_kwargs)
           ^^^^^^^^^^^^^^^^^^^^^^^^^^^^^^
  File "C:\My_programms\JetBrains\PyCharm Community Edition 2023.3.2\My_programms\tg_voise\.venv\Lib\site-packages\requests\sessions.py", line 703, in send
    r = adapter.send(request, **kwargs)
        ^^^^^^^^^^^^^^^^^^^^^^^^^^^^^^^
  File "C:\My_programms\JetBrains\PyCharm Community Edition 2023.3.2\My_programms\tg_voise\.venv\Lib\site-packages\requests\adapters.py", line 519, in send
    raise ConnectionError(e, request=request)
requests.exceptions.ConnectionError: HTTPSConnectionPool(host='api.telegram.org', port=443): Max retries exceeded with url: /bot6565406578:AAHJXXP9C3YuGGrZavTnkhlJTq4hQl1V3KE/getUpdates?offset=585466214&timeout=20 (Caused by NameResolutionError("<urllib3.connection.HTTPSConnection object at 0x0000018DBC3A9220>: Failed to resolve 'api.telegram.org' ([Errno 11001] getaddrinfo failed)"))

2024-04-12 23:37:44,022 - TeleBot - ERROR - Infinity polling exception: HTTPSConnectionPool(host='api.telegram.org', port=443): Max retries exceeded with url: /bot6565406578:AAHJXXP9C3YuGGrZavTnkhlJTq4hQl1V3KE/getUpdates?offset=585466214&timeout=20 (Caused by NameResolutionError("<urllib3.connection.HTTPSConnection object at 0x0000018DBCE3CA40>: Failed to resolve 'api.telegram.org' ([Errno 11001] getaddrinfo failed)"))
2024-04-12 23:37:44,025 - TeleBot - ERROR - Exception traceback:
Traceback (most recent call last):
  File "C:\My_programms\JetBrains\PyCharm Community Edition 2023.3.2\My_programms\tg_voise\.venv\Lib\site-packages\urllib3\connection.py", line 198, in _new_conn
    sock = connection.create_connection(
           ^^^^^^^^^^^^^^^^^^^^^^^^^^^^^
  File "C:\My_programms\JetBrains\PyCharm Community Edition 2023.3.2\My_programms\tg_voise\.venv\Lib\site-packages\urllib3\util\connection.py", line 60, in create_connection
    for res in socket.getaddrinfo(host, port, family, socket.SOCK_STREAM):
               ^^^^^^^^^^^^^^^^^^^^^^^^^^^^^^^^^^^^^^^^^^^^^^^^^^^^^^^^^^
  File "C:\Users\Asus\AppData\Local\Programs\Python\Python312\Lib\socket.py", line 963, in getaddrinfo
    for res in _socket.getaddrinfo(host, port, family, type, proto, flags):
               ^^^^^^^^^^^^^^^^^^^^^^^^^^^^^^^^^^^^^^^^^^^^^^^^^^^^^^^^^^^
socket.gaierror: [Errno 11001] getaddrinfo failed

The above exception was the direct cause of the following exception:

Traceback (most recent call last):
  File "C:\My_programms\JetBrains\PyCharm Community Edition 2023.3.2\My_programms\tg_voise\.venv\Lib\site-packages\urllib3\connectionpool.py", line 793, in urlopen
    response = self._make_request(
               ^^^^^^^^^^^^^^^^^^^
  File "C:\My_programms\JetBrains\PyCharm Community Edition 2023.3.2\My_programms\tg_voise\.venv\Lib\site-packages\urllib3\connectionpool.py", line 491, in _make_request
    raise new_e
  File "C:\My_programms\JetBrains\PyCharm Community Edition 2023.3.2\My_programms\tg_voise\.venv\Lib\site-packages\urllib3\connectionpool.py", line 467, in _make_request
    self._validate_conn(conn)
  File "C:\My_programms\JetBrains\PyCharm Community Edition 2023.3.2\My_programms\tg_voise\.venv\Lib\site-packages\urllib3\connectionpool.py", line 1099, in _validate_conn
    conn.connect()
  File "C:\My_programms\JetBrains\PyCharm Community Edition 2023.3.2\My_programms\tg_voise\.venv\Lib\site-packages\urllib3\connection.py", line 616, in connect
    self.sock = sock = self._new_conn()
                       ^^^^^^^^^^^^^^^^
  File "C:\My_programms\JetBrains\PyCharm Community Edition 2023.3.2\My_programms\tg_voise\.venv\Lib\site-packages\urllib3\connection.py", line 205, in _new_conn
    raise NameResolutionError(self.host, self, e) from e
urllib3.exceptions.NameResolutionError: <urllib3.connection.HTTPSConnection object at 0x0000018DBCE3CA40>: Failed to resolve 'api.telegram.org' ([Errno 11001] getaddrinfo failed)

The above exception was the direct cause of the following exception:

Traceback (most recent call last):
  File "C:\My_programms\JetBrains\PyCharm Community Edition 2023.3.2\My_programms\tg_voise\.venv\Lib\site-packages\requests\adapters.py", line 486, in send
    resp = conn.urlopen(
           ^^^^^^^^^^^^^
  File "C:\My_programms\JetBrains\PyCharm Community Edition 2023.3.2\My_programms\tg_voise\.venv\Lib\site-packages\urllib3\connectionpool.py", line 847, in urlopen
    retries = retries.increment(
              ^^^^^^^^^^^^^^^^^^
  File "C:\My_programms\JetBrains\PyCharm Community Edition 2023.3.2\My_programms\tg_voise\.venv\Lib\site-packages\urllib3\util\retry.py", line 515, in increment
    raise MaxRetryError(_pool, url, reason) from reason  # type: ignore[arg-type]
    ^^^^^^^^^^^^^^^^^^^^^^^^^^^^^^^^^^^^^^^^^^^^^^^^^^^
urllib3.exceptions.MaxRetryError: HTTPSConnectionPool(host='api.telegram.org', port=443): Max retries exceeded with url: /bot6565406578:AAHJXXP9C3YuGGrZavTnkhlJTq4hQl1V3KE/getUpdates?offset=585466214&timeout=20 (Caused by NameResolutionError("<urllib3.connection.HTTPSConnection object at 0x0000018DBCE3CA40>: Failed to resolve 'api.telegram.org' ([Errno 11001] getaddrinfo failed)"))

During handling of the above exception, another exception occurred:

Traceback (most recent call last):
  File "C:\My_programms\JetBrains\PyCharm Community Edition 2023.3.2\My_programms\tg_voise\.venv\Lib\site-packages\telebot\__init__.py", line 1081, in infinity_polling
    self.polling(non_stop=True, timeout=timeout, long_polling_timeout=long_polling_timeout,
  File "C:\My_programms\JetBrains\PyCharm Community Edition 2023.3.2\My_programms\tg_voise\.venv\Lib\site-packages\telebot\__init__.py", line 1169, in polling
    self.__threaded_polling(non_stop=non_stop, interval=interval, timeout=timeout, long_polling_timeout=long_polling_timeout,
  File "C:\My_programms\JetBrains\PyCharm Community Edition 2023.3.2\My_programms\tg_voise\.venv\Lib\site-packages\telebot\__init__.py", line 1244, in __threaded_polling
    raise e
  File "C:\My_programms\JetBrains\PyCharm Community Edition 2023.3.2\My_programms\tg_voise\.venv\Lib\site-packages\telebot\__init__.py", line 1205, in __threaded_polling
    polling_thread.raise_exceptions()
  File "C:\My_programms\JetBrains\PyCharm Community Edition 2023.3.2\My_programms\tg_voise\.venv\Lib\site-packages\telebot\util.py", line 111, in raise_exceptions
    raise self.exception_info
  File "C:\My_programms\JetBrains\PyCharm Community Edition 2023.3.2\My_programms\tg_voise\.venv\Lib\site-packages\telebot\util.py", line 93, in run
    task(*args, **kwargs)
  File "C:\My_programms\JetBrains\PyCharm Community Edition 2023.3.2\My_programms\tg_voise\.venv\Lib\site-packages\telebot\__init__.py", line 675, in __retrieve_updates
    updates = self.get_updates(offset=(self.last_update_id + 1),
             ^^^^^^^^^^^^^^^^^^^^^^^^^^^^^^^^^^^^^^^^^^^^^^^^^^
  File "C:\My_programms\JetBrains\PyCharm Community Edition 2023.3.2\My_programms\tg_voise\.venv\Lib\site-packages\telebot\__init__.py", line 647, in get_updates
    json_updates = apihelper.get_updates(
                   ^^^^^^^^^^^^^^^^^^^^^^
  File "C:\My_programms\JetBrains\PyCharm Community Edition 2023.3.2\My_programms\tg_voise\.venv\Lib\site-packages\telebot\apihelper.py", line 327, in get_updates
    return _make_request(token, method_url, params=payload)
           ^^^^^^^^^^^^^^^^^^^^^^^^^^^^^^^^^^^^^^^^^^^^^^^^
  File "C:\My_programms\JetBrains\PyCharm Community Edition 2023.3.2\My_programms\tg_voise\.venv\Lib\site-packages\telebot\apihelper.py", line 161, in _make_request
    result = _get_req_session().request(
             ^^^^^^^^^^^^^^^^^^^^^^^^^^^
  File "C:\My_programms\JetBrains\PyCharm Community Edition 2023.3.2\My_programms\tg_voise\.venv\Lib\site-packages\requests\sessions.py", line 589, in request
    resp = self.send(prep, **send_kwargs)
           ^^^^^^^^^^^^^^^^^^^^^^^^^^^^^^
  File "C:\My_programms\JetBrains\PyCharm Community Edition 2023.3.2\My_programms\tg_voise\.venv\Lib\site-packages\requests\sessions.py", line 703, in send
    r = adapter.send(request, **kwargs)
        ^^^^^^^^^^^^^^^^^^^^^^^^^^^^^^^
  File "C:\My_programms\JetBrains\PyCharm Community Edition 2023.3.2\My_programms\tg_voise\.venv\Lib\site-packages\requests\adapters.py", line 519, in send
    raise ConnectionError(e, request=request)
requests.exceptions.ConnectionError: HTTPSConnectionPool(host='api.telegram.org', port=443): Max retries exceeded with url: /bot6565406578:AAHJXXP9C3YuGGrZavTnkhlJTq4hQl1V3KE/getUpdates?offset=585466214&timeout=20 (Caused by NameResolutionError("<urllib3.connection.HTTPSConnection object at 0x0000018DBCE3CA40>: Failed to resolve 'api.telegram.org' ([Errno 11001] getaddrinfo failed)"))

2024-04-12 23:37:47,047 - TeleBot - ERROR - Infinity polling exception: HTTPSConnectionPool(host='api.telegram.org', port=443): Max retries exceeded with url: /bot6565406578:AAHJXXP9C3YuGGrZavTnkhlJTq4hQl1V3KE/getUpdates?offset=585466214&timeout=20 (Caused by NameResolutionError("<urllib3.connection.HTTPSConnection object at 0x0000018DBCE5EC00>: Failed to resolve 'api.telegram.org' ([Errno 11001] getaddrinfo failed)"))
2024-04-12 23:37:47,051 - TeleBot - ERROR - Exception traceback:
Traceback (most recent call last):
  File "C:\My_programms\JetBrains\PyCharm Community Edition 2023.3.2\My_programms\tg_voise\.venv\Lib\site-packages\urllib3\connection.py", line 198, in _new_conn
    sock = connection.create_connection(
           ^^^^^^^^^^^^^^^^^^^^^^^^^^^^^
  File "C:\My_programms\JetBrains\PyCharm Community Edition 2023.3.2\My_programms\tg_voise\.venv\Lib\site-packages\urllib3\util\connection.py", line 60, in create_connection
    for res in socket.getaddrinfo(host, port, family, socket.SOCK_STREAM):
               ^^^^^^^^^^^^^^^^^^^^^^^^^^^^^^^^^^^^^^^^^^^^^^^^^^^^^^^^^^
  File "C:\Users\Asus\AppData\Local\Programs\Python\Python312\Lib\socket.py", line 963, in getaddrinfo
    for res in _socket.getaddrinfo(host, port, family, type, proto, flags):
               ^^^^^^^^^^^^^^^^^^^^^^^^^^^^^^^^^^^^^^^^^^^^^^^^^^^^^^^^^^^
socket.gaierror: [Errno 11001] getaddrinfo failed

The above exception was the direct cause of the following exception:

Traceback (most recent call last):
  File "C:\My_programms\JetBrains\PyCharm Community Edition 2023.3.2\My_programms\tg_voise\.venv\Lib\site-packages\urllib3\connectionpool.py", line 793, in urlopen
    response = self._make_request(
               ^^^^^^^^^^^^^^^^^^^
  File "C:\My_programms\JetBrains\PyCharm Community Edition 2023.3.2\My_programms\tg_voise\.venv\Lib\site-packages\urllib3\connectionpool.py", line 491, in _make_request
    raise new_e
  File "C:\My_programms\JetBrains\PyCharm Community Edition 2023.3.2\My_programms\tg_voise\.venv\Lib\site-packages\urllib3\connectionpool.py", line 467, in _make_request
    self._validate_conn(conn)
  File "C:\My_programms\JetBrains\PyCharm Community Edition 2023.3.2\My_programms\tg_voise\.venv\Lib\site-packages\urllib3\connectionpool.py", line 1099, in _validate_conn
    conn.connect()
  File "C:\My_programms\JetBrains\PyCharm Community Edition 2023.3.2\My_programms\tg_voise\.venv\Lib\site-packages\urllib3\connection.py", line 616, in connect
    self.sock = sock = self._new_conn()
                       ^^^^^^^^^^^^^^^^
  File "C:\My_programms\JetBrains\PyCharm Community Edition 2023.3.2\My_programms\tg_voise\.venv\Lib\site-packages\urllib3\connection.py", line 205, in _new_conn
    raise NameResolutionError(self.host, self, e) from e
urllib3.exceptions.NameResolutionError: <urllib3.connection.HTTPSConnection object at 0x0000018DBCE5EC00>: Failed to resolve 'api.telegram.org' ([Errno 11001] getaddrinfo failed)

The above exception was the direct cause of the following exception:

Traceback (most recent call last):
  File "C:\My_programms\JetBrains\PyCharm Community Edition 2023.3.2\My_programms\tg_voise\.venv\Lib\site-packages\requests\adapters.py", line 486, in send
    resp = conn.urlopen(
           ^^^^^^^^^^^^^
  File "C:\My_programms\JetBrains\PyCharm Community Edition 2023.3.2\My_programms\tg_voise\.venv\Lib\site-packages\urllib3\connectionpool.py", line 847, in urlopen
    retries = retries.increment(
              ^^^^^^^^^^^^^^^^^^
  File "C:\My_programms\JetBrains\PyCharm Community Edition 2023.3.2\My_programms\tg_voise\.venv\Lib\site-packages\urllib3\util\retry.py", line 515, in increment
    raise MaxRetryError(_pool, url, reason) from reason  # type: ignore[arg-type]
    ^^^^^^^^^^^^^^^^^^^^^^^^^^^^^^^^^^^^^^^^^^^^^^^^^^^
urllib3.exceptions.MaxRetryError: HTTPSConnectionPool(host='api.telegram.org', port=443): Max retries exceeded with url: /bot6565406578:AAHJXXP9C3YuGGrZavTnkhlJTq4hQl1V3KE/getUpdates?offset=585466214&timeout=20 (Caused by NameResolutionError("<urllib3.connection.HTTPSConnection object at 0x0000018DBCE5EC00>: Failed to resolve 'api.telegram.org' ([Errno 11001] getaddrinfo failed)"))

During handling of the above exception, another exception occurred:

Traceback (most recent call last):
  File "C:\My_programms\JetBrains\PyCharm Community Edition 2023.3.2\My_programms\tg_voise\.venv\Lib\site-packages\telebot\__init__.py", line 1081, in infinity_polling
    self.polling(non_stop=True, timeout=timeout, long_polling_timeout=long_polling_timeout,
  File "C:\My_programms\JetBrains\PyCharm Community Edition 2023.3.2\My_programms\tg_voise\.venv\Lib\site-packages\telebot\__init__.py", line 1169, in polling
    self.__threaded_polling(non_stop=non_stop, interval=interval, timeout=timeout, long_polling_timeout=long_polling_timeout,
  File "C:\My_programms\JetBrains\PyCharm Community Edition 2023.3.2\My_programms\tg_voise\.venv\Lib\site-packages\telebot\__init__.py", line 1244, in __threaded_polling
    raise e
  File "C:\My_programms\JetBrains\PyCharm Community Edition 2023.3.2\My_programms\tg_voise\.venv\Lib\site-packages\telebot\__init__.py", line 1205, in __threaded_polling
    polling_thread.raise_exceptions()
  File "C:\My_programms\JetBrains\PyCharm Community Edition 2023.3.2\My_programms\tg_voise\.venv\Lib\site-packages\telebot\util.py", line 111, in raise_exceptions
    raise self.exception_info
  File "C:\My_programms\JetBrains\PyCharm Community Edition 2023.3.2\My_programms\tg_voise\.venv\Lib\site-packages\telebot\util.py", line 93, in run
    task(*args, **kwargs)
  File "C:\My_programms\JetBrains\PyCharm Community Edition 2023.3.2\My_programms\tg_voise\.venv\Lib\site-packages\telebot\__init__.py", line 675, in __retrieve_updates
    updates = self.get_updates(offset=(self.last_update_id + 1),
             ^^^^^^^^^^^^^^^^^^^^^^^^^^^^^^^^^^^^^^^^^^^^^^^^^^
  File "C:\My_programms\JetBrains\PyCharm Community Edition 2023.3.2\My_programms\tg_voise\.venv\Lib\site-packages\telebot\__init__.py", line 647, in get_updates
    json_updates = apihelper.get_updates(
                   ^^^^^^^^^^^^^^^^^^^^^^
  File "C:\My_programms\JetBrains\PyCharm Community Edition 2023.3.2\My_programms\tg_voise\.venv\Lib\site-packages\telebot\apihelper.py", line 327, in get_updates
    return _make_request(token, method_url, params=payload)
           ^^^^^^^^^^^^^^^^^^^^^^^^^^^^^^^^^^^^^^^^^^^^^^^^
  File "C:\My_programms\JetBrains\PyCharm Community Edition 2023.3.2\My_programms\tg_voise\.venv\Lib\site-packages\telebot\apihelper.py", line 161, in _make_request
    result = _get_req_session().request(
             ^^^^^^^^^^^^^^^^^^^^^^^^^^^
  File "C:\My_programms\JetBrains\PyCharm Community Edition 2023.3.2\My_programms\tg_voise\.venv\Lib\site-packages\requests\sessions.py", line 589, in request
    resp = self.send(prep, **send_kwargs)
           ^^^^^^^^^^^^^^^^^^^^^^^^^^^^^^
  File "C:\My_programms\JetBrains\PyCharm Community Edition 2023.3.2\My_programms\tg_voise\.venv\Lib\site-packages\requests\sessions.py", line 703, in send
    r = adapter.send(request, **kwargs)
        ^^^^^^^^^^^^^^^^^^^^^^^^^^^^^^^
  File "C:\My_programms\JetBrains\PyCharm Community Edition 2023.3.2\My_programms\tg_voise\.venv\Lib\site-packages\requests\adapters.py", line 519, in send
    raise ConnectionError(e, request=request)
requests.exceptions.ConnectionError: HTTPSConnectionPool(host='api.telegram.org', port=443): Max retries exceeded with url: /bot6565406578:AAHJXXP9C3YuGGrZavTnkhlJTq4hQl1V3KE/getUpdates?offset=585466214&timeout=20 (Caused by NameResolutionError("<urllib3.connection.HTTPSConnection object at 0x0000018DBCE5EC00>: Failed to resolve 'api.telegram.org' ([Errno 11001] getaddrinfo failed)"))

